{DataVersion:3465,size:[15,18,13],palette:[{Name:"minecraft:cobbled_deepslate"},{Name:"minecraft:deepslate_bricks"},{Name:"minecraft:oak_planks"},{Name:"minecraft:stripped_spruce_log",Properties:{axis:"y"}},{Name:"minecraft:stripped_spruce_log",Properties:{axis:"x"}},{Name:"minecraft:stripped_spruce_log",Properties:{axis:"z"}},{Name:"minecraft:white_wool"},{Name:"minecraft:glass_pane"},{Name:"minecraft:spruce_door",Properties:{facing:"south",half:"lower"}},{Name:"minecraft:spruce_door",Properties:{facing:"south",half:"upper"}},{Name:"minecraft:dark_oak_stairs",Properties:{facing:"north"}},{Name:"minecraft:dark_oak_stairs",Properties:{facing:"south"}},{Name:"minecraft:dark_oak_stairs",Properties:{facing:"east"}},{Name:"minecraft:dark_oak_stairs",Properties:{facing:"west"}},{Name:"minecraft:stone_bricks"},{Name:"minecraft:campfire",Properties:{lit:"true"}},{Name:"minecraft:oak_leaves"},{Name:"minecraft:lantern",Properties:{hanging:"false"}},{Name:"minecraft:spruce_trapdoor",Properties:{half:"top",open:"false"}},{Name:"minecraft:crafting_table"},{Name:"minecraft:furnace",Properties:{facing:"west"}},{Name:"minecraft:bookshelf"},{Name:"minecraft:red_bed",Properties:{facing:"west",part:"head"}},{Name:"minecraft:red_bed",Properties:{facing:"west",part:"foot"}},{Name:"minecraft:chest",Properties:{facing:"west"}},{Name:"minecraft:torch"},{Name:"minecraft:cobweb"},{Name:"minecraft:dark_oak_slab"},{Name:"minecraft:spruce_stairs",Properties:{facing:"south"}}],blocks:[{pos:[2,0,2],state:1},{pos:[3,0,2],state:1},{pos:[4,0,2],state:1},{pos:[5,0,2],state:1},{pos:[6,0,2],state:1},{pos:[7,0,2],state:1},{pos:[8,0,2],state:1},{pos:[9,0,2],state:1},{pos:[10,0,2],state:1},{pos:[11,0,2],state:1},{pos:[12,0,2],state:1},{pos:[2,0,3],state:1},{pos:[3,0,3],state:0},{pos:[4,0,3],state:0},{pos:[5,0,3],state:0},{pos:[6,0,3],state:0},{pos:[7,0,3],state:0},{pos:[8,0,3],state:0},{pos:[9,0,3],state:0},{pos:[10,0,3],state:0},{pos:[11,0,3],state:0},{pos:[12,0,3],state:1},{pos:[2,0,4],state:1},{pos:[3,0,4],state:0},{pos:[4,0,4],state:0},{pos:[5,0,4],state:0},{pos:[6,0,4],state:0},{pos:[7,0,4],state:0},{pos:[8,0,4],state:0},{pos:[9,0,4],state:0},{pos:[10,0,4],state:0},{pos:[11,0,4],state:0},{pos:[12,0,4],state:1},{pos:[2,0,5],state:1},{pos:[3,0,5],state:0},{pos:[4,0,5],state:0},{pos:[5,0,5],state:0},{pos:[6,0,5],state:0},{pos:[7,0,5],state:0},{pos:[8,0,5],state:0},{pos:[9,0,5],state:0},{pos:[10,0,5],state:0},{pos:[11,0,5],state:0},{pos:[12,0,5],state:1},{pos:[2,0,6],state:1},{pos:[3,0,6],state:0},{pos:[4,0,6],state:0},{pos:[5,0,6],state:0},{pos:[6,0,6],state:0},{pos:[7,0,6],state:0},{pos:[8,0,6],state:0},{pos:[9,0,6],state:0},{pos:[10,0,6],state:0},{pos:[11,0,6],state:0},{pos:[12,0,6],state:1},{pos:[2,0,7],state:1},{pos:[3,0,7],state:0},{pos:[4,0,7],state:0},{pos:[5,0,7],state:0},{pos:[6,0,7],state:0},{pos:[7,0,7],state:0},{pos:[8,0,7],state:0},{pos:[9,0,7],state:0},{pos:[10,0,7],state:0},{pos:[11,0,7],state:0},{pos:[12,0,7],state:1},{pos:[2,0,8],state:1},{pos:[3,0,8],state:0},{pos:[4,0,8],state:0},{pos:[5,0,8],state:0},{pos:[6,0,8],state:0},{pos:[7,0,8],state:0},{pos:[8,0,8],state:0},{pos:[9,0,8],state:0},{pos:[10,0,8],state:0},{pos:[11,0,8],state:0},{pos:[12,0,8],state:1},{pos:[2,0,9],state:1},{pos:[3,0,9],state:1},{pos:[4,0,9],state:1},{pos:[5,0,9],state:1},{pos:[6,0,9],state:1},{pos:[7,0,9],state:1},{pos:[8,0,9],state:1},{pos:[9,0,9],state:1},{pos:[10,0,9],state:1},{pos:[11,0,9],state:1},{pos:[12,0,9],state:1},{pos:[3,1,3],state:2},{pos:[4,1,3],state:2},{pos:[5,1,3],state:2},{pos:[6,1,3],state:2},{pos:[7,1,3],state:2},{pos:[8,1,3],state:2},{pos:[9,1,3],state:2},{pos:[10,1,3],state:2},{pos:[11,1,3],state:2},{pos:[3,1,4],state:2},{pos:[4,1,4],state:2},{pos:[5,1,4],state:2},{pos:[6,1,4],state:2},{pos:[7,1,4],state:2},{pos:[8,1,4],state:2},{pos:[9,1,4],state:2},{pos:[10,1,4],state:2},{pos:[11,1,4],state:2},{pos:[3,1,5],state:2},{pos:[4,1,5],state:2},{pos:[5,1,5],state:2},{pos:[6,1,5],state:2},{pos:[7,1,5],state:2},{pos:[8,1,5],state:2},{pos:[9,1,5],state:2},{pos:[10,1,5],state:2},{pos:[11,1,5],state:2},{pos:[3,1,6],state:2},{pos:[4,1,6],state:2},{pos:[5,1,6],state:2},{pos:[6,1,6],state:2},{pos:[7,1,6],state:2},{pos:[8,1,6],state:2},{pos:[9,1,6],state:2},{pos:[10,1,6],state:2},{pos:[11,1,6],state:2},{pos:[3,1,7],state:2},{pos:[4,1,7],state:2},{pos:[5,1,7],state:2},{pos:[6,1,7],state:2},{pos:[7,1,7],state:2},{pos:[8,1,7],state:2},{pos:[9,1,7],state:2},{pos:[10,1,7],state:2},{pos:[11,1,7],state:2},{pos:[3,1,8],state:2},{pos:[4,1,8],state:2},{pos:[5,1,8],state:2},{pos:[6,1,8],state:2},{pos:[7,1,8],state:2},{pos:[8,1,8],state:2},{pos:[9,1,8],state:2},{pos:[10,1,8],state:2},{pos:[11,1,8],state:2},{pos:[2,1,2],state:3},{pos:[12,1,2],state:3},{pos:[2,1,9],state:3},{pos:[12,1,9],state:3},{pos:[2,1,3],state:6},{pos:[2,1,4],state:6},{pos:[2,1,5],state:6},{pos:[2,1,6],state:6},{pos:[2,1,7],state:6},{pos:[2,1,8],state:6},{pos:[12,1,3],state:6},{pos:[12,1,4],state:6},{pos:[12,1,5],state:6},{pos:[12,1,6],state:6},{pos:[12,1,7],state:6},{pos:[12,1,8],state:6},{pos:[3,1,2],state:6},{pos:[4,1,2],state:6},{pos:[5,1,2],state:6},{pos:[6,1,2],state:6},{pos:[7,1,2],state:6},{pos:[8,1,2],state:6},{pos:[9,1,2],state:6},{pos:[10,1,2],state:6},{pos:[11,1,2],state:6},{pos:[3,1,9],state:6},{pos:[4,1,9],state:6},{pos:[5,1,9],state:6},{pos:[6,1,9],state:6},{pos:[8,1,9],state:6},{pos:[9,1,9],state:6},{pos:[10,1,9],state:6},{pos:[11,1,9],state:6},{pos:[7,1,9],state:8},{pos:[1,1,2],state:16},{pos:[1,1,3],state:16},{pos:[1,1,8],state:16},{pos:[1,1,9],state:16},{pos:[13,1,2],state:16},{pos:[13,1,9],state:16},{pos:[11,2,3],state:21},{pos:[11,2,4],state:21},{pos:[11,2,5],state:21},{pos:[11,3,3],state:21},{pos:[11,3,4],state:21},{pos:[11,3,5],state:21},{pos:[11,4,3],state:21},{pos:[11,4,4],state:21},{pos:[11,4,5],state:21},{pos:[2,2,2],state:3},{pos:[12,2,2],state:3},{pos:[2,2,9],state:3},{pos:[12,2,9],state:3},{pos:[2,2,3],state:6},{pos:[2,2,4],state:6},{pos:[2,2,5],state:7},{pos:[2,2,6],state:6},{pos:[2,2,7],state:6},{pos:[2,2,8],state:6},{pos:[12,2,3],state:6},{pos:[12,2,4],state:6},{pos:[12,2,5],state:6},{pos:[12,2,6],state:7},{pos:[12,2,7],state:6},{pos:[12,2,8],state:6},{pos:[3,2,2],state:6},{pos:[4,2,2],state:6},{pos:[5,2,2],state:7},{pos:[6,2,2],state:6},{pos:[7,2,2],state:6},{pos:[8,2,2],state:6},{pos:[9,2,2],state:7},{pos:[10,2,2],state:6},{pos:[11,2,2],state:6},{pos:[3,2,9],state:6},{pos:[4,2,9],state:6},{pos:[5,2,9],state:6},{pos:[6,2,9],state:6},{pos:[8,2,9],state:6},{pos:[9,2,9],state:6},{pos:[10,2,9],state:6},{pos:[11,2,9],state:6},{pos:[7,2,9],state:9},{pos:[3,2,8],state:19},{pos:[3,2,7],state:20},{pos:[4,2,7],state:24},{pos:[12,2,2],state:14},{pos:[12,3,2],state:14},{pos:[12,4,2],state:14},{pos:[12,5,2],state:14},{pos:[12,6,2],state:14},{pos:[12,7,2],state:14},{pos:[12,8,2],state:14},{pos:[12,9,2],state:14},{pos:[12,10,2],state:14},{pos:[12,11,2],state:14},{pos:[12,12,2],state:14},{pos:[12,13,2],state:14},{pos:[12,14,2],state:14},{pos:[12,15,2],state:15},{pos:[2,3,2],state:3},{pos:[12,3,2],state:3},{pos:[2,3,9],state:3},{pos:[12,3,9],state:3},{pos:[2,3,3],state:6},{pos:[2,3,4],state:6},{pos:[2,3,5],state:7},{pos:[2,3,6],state:6},{pos:[2,3,7],state:6},{pos:[2,3,8],state:6},{pos:[12,3,3],state:6},{pos:[12,3,4],state:6},{pos:[12,3,5],state:6},{pos:[12,3,6],state:7},{pos:[12,3,7],state:6},{pos:[12,3,8],state:6},{pos:[3,3,2],state:6},{pos:[4,3,2],state:6},{pos:[5,3,2],state:7},{pos:[6,3,2],state:6},{pos:[7,3,2],state:6},{pos:[8,3,2],state:6},{pos:[9,3,2],state:7},{pos:[10,3,2],state:6},{pos:[11,3,2],state:6},{pos:[3,3,9],state:6},{pos:[4,3,9],state:6},{pos:[5,3,9],state:6},{pos:[6,3,9],state:6},{pos:[7,3,9],state:6},{pos:[8,3,9],state:6},{pos:[9,3,9],state:6},{pos:[10,3,9],state:6},{pos:[11,3,9],state:6},{pos:[10,3,3],state:25},{pos:[2,4,2],state:3},{pos:[12,4,2],state:3},{pos:[2,4,9],state:3},{pos:[12,4,9],state:3},{pos:[2,4,3],state:6},{pos:[2,4,4],state:6},{pos:[2,4,5],state:6},{pos:[2,4,6],state:6},{pos:[2,4,7],state:6},{pos:[2,4,8],state:6},{pos:[12,4,3],state:6},{pos:[12,4,4],state:6},{pos:[12,4,5],state:6},{pos:[12,4,6],state:6},{pos:[12,4,7],state:6},{pos:[12,4,8],state:6},{pos:[3,4,2],state:6},{pos:[4,4,2],state:6},{pos:[5,4,2],state:6},{pos:[6,4,2],state:6},{pos:[7,4,2],state:6},{pos:[8,4,2],state:6},{pos:[9,4,2],state:6},{pos:[10,4,2],state:6},{pos:[11,4,2],state:6},{pos:[3,4,9],state:6},{pos:[4,4,9],state:6},{pos:[5,4,9],state:6},{pos:[6,4,9],state:6},{pos:[7,4,9],state:6},{pos:[8,4,9],state:6},{pos:[9,4,9],state:6},{pos:[10,4,9],state:6},{pos:[11,4,9],state:6},{pos:[6,4,10],state:28},{pos:[7,4,10],state:28},{pos:[8,4,10],state:28},{pos:[1,5,2],state:3},{pos:[1,5,3],state:5},{pos:[1,5,4],state:5},{pos:[1,5,5],state:5},{pos:[1,5,6],state:5},{pos:[1,5,7],state:5},{pos:[1,5,8],state:5},{pos:[1,5,9],state:3},{pos:[13,5,2],state:3},{pos:[13,5,3],state:5},{pos:[13,5,4],state:5},{pos:[13,5,5],state:5},{pos:[13,5,6],state:5},{pos:[13,5,7],state:5},{pos:[13,5,8],state:5},{pos:[13,5,9],state:3},{pos:[2,5,1],state:4},{pos:[3,5,1],state:4},{pos:[4,5,1],state:4},{pos:[5,5,1],state:4},{pos:[6,5,1],state:4},{pos:[7,5,1],state:4},{pos:[8,5,1],state:4},{pos:[9,5,1],state:4},{pos:[10,5,1],state:4},{pos:[11,5,1],state:4},{pos:[12,5,1],state:4},{pos:[2,5,10],state:4},{pos:[3,5,10],state:4},{pos:[4,5,10],state:4},{pos:[5,5,10],state:4},{pos:[6,5,10],state:4},{pos:[7,5,10],state:4},{pos:[8,5,10],state:4},{pos:[9,5,10],state:4},{pos:[10,5,10],state:4},{pos:[11,5,10],state:4},{pos:[12,5,10],state:4},{pos:[2,5,2],state:3},{pos:[2,5,9],state:3},{pos:[12,5,2],state:3},{pos:[12,5,9],state:3},{pos:[1,4,2],state:17},{pos:[13,4,2],state:17},{pos:[1,4,9],state:17},{pos:[13,4,9],state:17},{pos:[2,5,3],state:2},{pos:[2,5,4],state:2},{pos:[2,5,5],state:2},{pos:[2,5,6],state:2},{pos:[2,5,7],state:2},{pos:[2,5,8],state:2},{pos:[3,5,2],state:2},{pos:[3,5,3],state:2},{pos:[3,5,4],state:2},{pos:[3,5,5],state:2},{pos:[3,5,6],state:2},{pos:[3,5,7],state:2},{pos:[3,5,8],state:2},{pos:[3,5,9],state:2},{pos:[4,5,2],state:2},{pos:[4,5,3],state:2},{pos:[4,5,4],state:2},{pos:[4,5,5],state:2},{pos:[4,5,6],state:2},{pos:[4,5,7],state:2},{pos:[4,5,8],state:2},{pos:[4,5,9],state:2},{pos:[5,5,2],state:2},{pos:[5,5,3],state:2},{pos:[5,5,4],state:2},{pos:[5,5,5],state:2},{pos:[5,5,6],state:2},{pos:[5,5,7],state:2},{pos:[5,5,8],state:2},{pos:[5,5,9],state:2},{pos:[6,5,2],state:2},{pos:[6,5,3],state:2},{pos:[6,5,4],state:2},{pos:[6,5,5],state:2},{pos:[6,5,6],state:2},{pos:[6,5,7],state:2},{pos:[6,5,8],state:2},{pos:[6,5,9],state:2},{pos:[7,5,2],state:2},{pos:[7,5,3],state:2},{pos:[7,5,4],state:2},{pos:[7,5,5],state:2},{pos:[7,5,6],state:2},{pos:[7,5,7],state:2},{pos:[7,5,8],state:2},{pos:[7,5,9],state:2},{pos:[8,5,2],state:2},{pos:[8,5,3],state:2},{pos:[8,5,4],state:2},{pos:[8,5,5],state:2},{pos:[8,5,6],state:2},{pos:[8,5,7],state:2},{pos:[8,5,8],state:2},{pos:[8,5,9],state:2},{pos:[9,5,2],state:2},{pos:[9,5,3],state:2},{pos:[9,5,4],state:2},{pos:[9,5,5],state:2},{pos:[9,5,6],state:2},{pos:[9,5,7],state:2},{pos:[9,5,8],state:2},{pos:[9,5,9],state:2},{pos:[10,5,2],state:2},{pos:[10,5,3],state:2},{pos:[10,5,4],state:2},{pos:[10,5,5],state:2},{pos:[10,5,6],state:2},{pos:[10,5,7],state:2},{pos:[10,5,8],state:2},{pos:[10,5,9],state:2},{pos:[11,5,2],state:2},{pos:[11,5,3],state:2},{pos:[11,5,4],state:2},{pos:[11,5,5],state:2},{pos:[11,5,6],state:2},{pos:[11,5,7],state:2},{pos:[11,5,8],state:2},{pos:[11,5,9],state:2},{pos:[12,5,3],state:2},{pos:[12,5,4],state:2},{pos:[12,5,5],state:2},{pos:[12,5,6],state:2},{pos:[12,5,7],state:2},{pos:[12,5,8],state:2},{pos:[1,6,2],state:3},{pos:[13,6,2],state:3},{pos:[1,6,9],state:3},{pos:[13,6,9],state:3},{pos:[2,6,2],state:6},{pos:[2,6,9],state:6},{pos:[12,6,2],state:6},{pos:[12,6,9],state:6},{pos:[1,6,3],state:6},{pos:[1,6,4],state:6},{pos:[1,6,5],state:7},{pos:[1,6,6],state:6},{pos:[1,6,7],state:6},{pos:[1,6,8],state:6},{pos:[13,6,3],state:6},{pos:[13,6,4],state:6},{pos:[13,6,5],state:6},{pos:[13,6,6],state:7},{pos:[13,6,7],state:6},{pos:[13,6,8],state:6},{pos:[2,6,1],state:6},{pos:[3,6,1],state:6},{pos:[4,6,1],state:6},{pos:[5,6,1],state:6},{pos:[6,6,1],state:7},{pos:[7,6,1],state:6},{pos:[8,6,1],state:7},{pos:[9,6,1],state:6},{pos:[10,6,1],state:6},{pos:[11,6,1],state:6},{pos:[12,6,1],state:6},{pos:[2,6,10],state:6},{pos:[3,6,10],state:6},{pos:[4,6,10],state:6},{pos:[5,6,10],state:6},{pos:[6,6,10],state:7},{pos:[7,6,10],state:6},{pos:[8,6,10],state:7},{pos:[9,6,10],state:6},{pos:[10,6,10],state:6},{pos:[11,6,10],state:6},{pos:[12,6,10],state:6},{pos:[10,6,3],state:23},{pos:[11,6,3],state:22},{pos:[11,6,8],state:19},{pos:[1,7,2],state:3},{pos:[13,7,2],state:3},{pos:[1,7,9],state:3},{pos:[13,7,9],state:3},{pos:[2,7,2],state:6},{pos:[2,7,9],state:6},{pos:[12,7,2],state:6},{pos:[12,7,9],state:6},{pos:[1,7,3],state:6},{pos:[1,7,4],state:6},{pos:[1,7,5],state:7},{pos:[1,7,6],state:6},{pos:[1,7,7],state:6},{pos:[1,7,8],state:6},{pos:[13,7,3],state:6},{pos:[13,7,4],state:6},{pos:[13,7,5],state:6},{pos:[13,7,6],state:7},{pos:[13,7,7],state:6},{pos:[13,7,8],state:6},{pos:[2,7,1],state:6},{pos:[3,7,1],state:6},{pos:[4,7,1],state:6},{pos:[5,7,1],state:6},{pos:[6,7,1],state:7},{pos:[7,7,1],state:6},{pos:[8,7,1],state:7},{pos:[9,7,1],state:6},{pos:[10,7,1],state:6},{pos:[11,7,1],state:6},{pos:[12,7,1],state:6},{pos:[2,7,10],state:6},{pos:[3,7,10],state:6},{pos:[4,7,10],state:6},{pos:[5,7,10],state:6},{pos:[6,7,10],state:7},{pos:[7,7,10],state:6},{pos:[8,7,10],state:7},{pos:[9,7,10],state:6},{pos:[10,7,10],state:6},{pos:[11,7,10],state:6},{pos:[12,7,10],state:6},{pos:[1,8,2],state:3},{pos:[13,8,2],state:3},{pos:[1,8,9],state:3},{pos:[13,8,9],state:3},{pos:[2,8,2],state:6},{pos:[2,8,9],state:6},{pos:[12,8,2],state:6},{pos:[12,8,9],state:6},{pos:[1,8,3],state:6},{pos:[1,8,4],state:6},{pos:[1,8,5],state:6},{pos:[1,8,6],state:6},{pos:[1,8,7],state:6},{pos:[1,8,8],state:6},{pos:[13,8,3],state:6},{pos:[13,8,4],state:6},{pos:[13,8,5],state:6},{pos:[13,8,6],state:6},{pos:[13,8,7],state:6},{pos:[13,8,8],state:6},{pos:[2,8,1],state:6},{pos:[3,8,1],state:6},{pos:[4,8,1],state:6},{pos:[5,8,1],state:6},{pos:[6,8,1],state:6},{pos:[7,8,1],state:6},{pos:[8,8,1],state:6},{pos:[9,8,1],state:6},{pos:[10,8,1],state:6},{pos:[11,8,1],state:6},{pos:[12,8,1],state:6},{pos:[2,8,10],state:6},{pos:[3,8,10],state:6},{pos:[4,8,10],state:6},{pos:[5,8,10],state:6},{pos:[6,8,10],state:6},{pos:[7,8,10],state:6},{pos:[8,8,10],state:6},{pos:[9,8,10],state:6},{pos:[10,8,10],state:6},{pos:[11,8,10],state:6},{pos:[12,8,10],state:6},{pos:[1,9,2],state:4},{pos:[1,9,3],state:4},{pos:[1,9,4],state:4},{pos:[1,9,5],state:4},{pos:[1,9,6],state:4},{pos:[1,9,7],state:4},{pos:[1,9,8],state:4},{pos:[1,9,9],state:4},{pos:[13,9,2],state:4},{pos:[13,9,3],state:4},{pos:[13,9,4],state:4},{pos:[13,9,5],state:4},{pos:[13,9,6],state:4},{pos:[13,9,7],state:4},{pos:[13,9,8],state:4},{pos:[13,9,9],state:4},{pos:[2,9,1],state:5},{pos:[3,9,1],state:5},{pos:[4,9,1],state:5},{pos:[5,9,1],state:5},{pos:[6,9,1],state:5},{pos:[7,9,1],state:5},{pos:[8,9,1],state:5},{pos:[9,9,1],state:5},{pos:[10,9,1],state:5},{pos:[11,9,1],state:5},{pos:[12,9,1],state:5},{pos:[2,9,10],state:5},{pos:[3,9,10],state:5},{pos:[4,9,10],state:5},{pos:[5,9,10],state:5},{pos:[6,9,10],state:5},{pos:[7,9,10],state:5},{pos:[8,9,10],state:5},{pos:[9,9,10],state:5},{pos:[10,9,10],state:5},{pos:[11,9,10],state:5},{pos:[12,9,10],state:5},{pos:[1,8,2],state:17},{pos:[13,8,2],state:17},{pos:[1,8,9],state:17},{pos:[13,8,9],state:17},{pos:[0,9,0],state:11},{pos:[1,9,0],state:11},{pos:[2,9,0],state:11},{pos:[3,9,0],state:11},{pos:[4,9,0],state:11},{pos:[5,9,0],state:11},{pos:[6,9,0],state:11},{pos:[7,9,0],state:11},{pos:[8,9,0],state:11},{pos:[9,9,0],state:11},{pos:[10,9,0],state:11},{pos:[11,9,0],state:11},{pos:[12,9,0],state:11},{pos:[13,9,0],state:11},{pos:[14,9,0],state:11},{pos:[0,9,11],state:10},{pos:[1,9,11],state:10},{pos:[2,9,11],state:10},{pos:[3,9,11],state:10},{pos:[4,9,11],state:10},{pos:[5,9,11],state:10},{pos:[6,9,11],state:10},{pos:[7,9,11],state:10},{pos:[8,9,11],state:10},{pos:[9,9,11],state:10},{pos:[10,9,11],state:10},{pos:[11,9,11],state:10},{pos:[12,9,11],state:10},{pos:[13,9,11],state:10},{pos:[14,9,11],state:10},{pos:[0,10,1],state:11},{pos:[1,10,1],state:11},{pos:[2,10,1],state:11},{pos:[3,10,1],state:11},{pos:[4,10,1],state:11},{pos:[5,10,1],state:11},{pos:[6,10,1],state:11},{pos:[7,10,1],state:11},{pos:[8,10,1],state:11},{pos:[9,10,1],state:11},{pos:[10,10,1],state:11},{pos:[11,10,1],state:11},{pos:[12,10,1],state:11},{pos:[13,10,1],state:11},{pos:[14,10,1],state:11},{pos:[0,10,10],state:10},{pos:[1,10,10],state:10},{pos:[2,10,10],state:10},{pos:[3,10,10],state:10},{pos:[4,10,10],state:10},{pos:[5,10,10],state:10},{pos:[6,10,10],state:10},{pos:[7,10,10],state:10},{pos:[8,10,10],state:10},{pos:[9,10,10],state:10},{pos:[10,10,10],state:10},{pos:[11,10,10],state:10},{pos:[12,10,10],state:10},{pos:[13,10,10],state:10},{pos:[14,10,10],state:10},{pos:[1,10,2],state:6},{pos:[2,10,2],state:6},{pos:[3,10,2],state:6},{pos:[4,10,2],state:6},{pos:[5,10,2],state:6},{pos:[6,10,2],state:6},{pos:[7,10,2],state:6},{pos:[8,10,2],state:6},{pos:[9,10,2],state:6},{pos:[10,10,2],state:6},{pos:[11,10,2],state:6},{pos:[12,10,2],state:6},{pos:[13,10,2],state:6},{pos:[1,10,9],state:6},{pos:[2,10,9],state:6},{pos:[3,10,9],state:6},{pos:[4,10,9],state:6},{pos:[5,10,9],state:6},{pos:[6,10,9],state:6},{pos:[7,10,9],state:6},{pos:[8,10,9],state:6},{pos:[9,10,9],state:6},{pos:[10,10,9],state:6},{pos:[11,10,9],state:6},{pos:[12,10,9],state:6},{pos:[13,10,9],state:6},{pos:[0,11,2],state:11},{pos:[1,11,2],state:11},{pos:[2,11,2],state:11},{pos:[3,11,2],state:11},{pos:[4,11,2],state:11},{pos:[5,11,2],state:11},{pos:[6,11,2],state:11},{pos:[7,11,2],state:11},{pos:[8,11,2],state:11},{pos:[9,11,2],state:11},{pos:[10,11,2],state:11},{pos:[11,11,2],state:11},{pos:[12,11,2],state:11},{pos:[13,11,2],state:11},{pos:[14,11,2],state:11},{pos:[0,11,9],state:10},{pos:[1,11,9],state:10},{pos:[2,11,9],state:10},{pos:[3,11,9],state:10},{pos:[4,11,9],state:10},{pos:[5,11,9],state:10},{pos:[6,11,9],state:10},{pos:[7,11,9],state:10},{pos:[8,11,9],state:10},{pos:[9,11,9],state:10},{pos:[10,11,9],state:10},{pos:[11,11,9],state:10},{pos:[12,11,9],state:10},{pos:[13,11,9],state:10},{pos:[14,11,9],state:10},{pos:[1,11,3],state:6},{pos:[2,11,3],state:6},{pos:[3,11,3],state:6},{pos:[4,11,3],state:6},{pos:[5,11,3],state:6},{pos:[6,11,3],state:6},{pos:[7,11,3],state:6},{pos:[8,11,3],state:6},{pos:[9,11,3],state:6},{pos:[10,11,3],state:6},{pos:[11,11,3],state:6},{pos:[12,11,3],state:6},{pos:[13,11,3],state:6},{pos:[1,11,8],state:6},{pos:[2,11,8],state:6},{pos:[3,11,8],state:6},{pos:[4,11,8],state:6},{pos:[5,11,8],state:6},{pos:[6,11,8],state:6},{pos:[7,11,8],state:6},{pos:[8,11,8],state:6},{pos:[9,11,8],state:6},{pos:[10,11,8],state:6},{pos:[11,11,8],state:6},{pos:[12,11,8],state:6},{pos:[13,11,8],state:6},{pos:[0,12,3],state:11},{pos:[1,12,3],state:11},{pos:[2,12,3],state:11},{pos:[3,12,3],state:11},{pos:[4,12,3],state:11},{pos:[5,12,3],state:11},{pos:[6,12,3],state:11},{pos:[7,12,3],state:11},{pos:[8,12,3],state:11},{pos:[9,12,3],state:11},{pos:[10,12,3],state:11},{pos:[11,12,3],state:11},{pos:[12,12,3],state:11},{pos:[13,12,3],state:11},{pos:[14,12,3],state:11},{pos:[0,12,8],state:10},{pos:[1,12,8],state:10},{pos:[2,12,8],state:10},{pos:[3,12,8],state:10},{pos:[4,12,8],state:10},{pos:[5,12,8],state:10},{pos:[6,12,8],state:10},{pos:[7,12,8],state:10},{pos:[8,12,8],state:10},{pos:[9,12,8],state:10},{pos:[10,12,8],state:10},{pos:[11,12,8],state:10},{pos:[12,12,8],state:10},{pos:[13,12,8],state:10},{pos:[14,12,8],state:10},{pos:[1,12,4],state:6},{pos:[2,12,4],state:6},{pos:[3,12,4],state:6},{pos:[4,12,4],state:6},{pos:[5,12,4],state:6},{pos:[6,12,4],state:6},{pos:[7,12,4],state:6},{pos:[8,12,4],state:6},{pos:[9,12,4],state:6},{pos:[10,12,4],state:6},{pos:[11,12,4],state:6},{pos:[12,12,4],state:6},{pos:[13,12,4],state:6},{pos:[1,12,7],state:6},{pos:[2,12,7],state:6},{pos:[3,12,7],state:6},{pos:[4,12,7],state:6},{pos:[5,12,7],state:6},{pos:[6,12,7],state:6},{pos:[7,12,7],state:6},{pos:[8,12,7],state:6},{pos:[9,12,7],state:6},{pos:[10,12,7],state:6},{pos:[11,12,7],state:6},{pos:[12,12,7],state:6},{pos:[13,12,7],state:6},{pos:[0,13,4],state:11},{pos:[1,13,4],state:11},{pos:[2,13,4],state:11},{pos:[3,13,4],state:11},{pos:[4,13,4],state:11},{pos:[5,13,4],state:11},{pos:[6,13,4],state:11},{pos:[7,13,4],state:11},{pos:[8,13,4],state:11},{pos:[9,13,4],state:11},{pos:[10,13,4],state:11},{pos:[11,13,4],state:11},{pos:[12,13,4],state:11},{pos:[13,13,4],state:11},{pos:[14,13,4],state:11},{pos:[0,13,7],state:10},{pos:[1,13,7],state:10},{pos:[2,13,7],state:10},{pos:[3,13,7],state:10},{pos:[4,13,7],state:10},{pos:[5,13,7],state:10},{pos:[6,13,7],state:10},{pos:[7,13,7],state:10},{pos:[8,13,7],state:10},{pos:[9,13,7],state:10},{pos:[10,13,7],state:10},{pos:[11,13,7],state:10},{pos:[12,13,7],state:10},{pos:[13,13,7],state:10},{pos:[14,13,7],state:10},{pos:[1,13,5],state:6},{pos:[2,13,5],state:6},{pos:[3,13,5],state:6},{pos:[4,13,5],state:6},{pos:[5,13,5],state:6},{pos:[6,13,5],state:6},{pos:[7,13,5],state:6},{pos:[8,13,5],state:6},{pos:[9,13,5],state:6},{pos:[10,13,5],state:6},{pos:[11,13,5],state:6},{pos:[12,13,5],state:6},{pos:[13,13,5],state:6},{pos:[1,13,6],state:6},{pos:[2,13,6],state:6},{pos:[3,13,6],state:6},{pos:[4,13,6],state:6},{pos:[5,13,6],state:6},{pos:[6,13,6],state:6},{pos:[7,13,6],state:6},{pos:[8,13,6],state:6},{pos:[9,13,6],state:6},{pos:[10,13,6],state:6},{pos:[11,13,6],state:6},{pos:[12,13,6],state:6},{pos:[13,13,6],state:6},{pos:[0,14,5],state:11},{pos:[1,14,5],state:11},{pos:[2,14,5],state:11},{pos:[3,14,5],state:11},{pos:[4,14,5],state:11},{pos:[5,14,5],state:11},{pos:[6,14,5],state:11},{pos:[7,14,5],state:11},{pos:[8,14,5],state:11},{pos:[9,14,5],state:11},{pos:[10,14,5],state:11},{pos:[11,14,5],state:11},{pos:[12,14,5],state:11},{pos:[13,14,5],state:11},{pos:[14,14,5],state:11},{pos:[0,14,6],state:10},{pos:[1,14,6],state:10},{pos:[2,14,6],state:10},{pos:[3,14,6],state:10},{pos:[4,14,6],state:10},{pos:[5,14,6],state:10},{pos:[6,14,6],state:10},{pos:[7,14,6],state:10},{pos:[8,14,6],state:10},{pos:[9,14,6],state:10},{pos:[10,14,6],state:10},{pos:[11,14,6],state:10},{pos:[12,14,6],state:10},{pos:[13,14,6],state:10},{pos:[14,14,6],state:10},{pos:[0,15,5],state:27},{pos:[1,15,5],state:27},{pos:[2,15,5],state:27},{pos:[3,15,5],state:27},{pos:[4,15,5],state:27},{pos:[5,15,5],state:27},{pos:[6,15,5],state:27},{pos:[7,15,5],state:27},{pos:[8,15,5],state:27},{pos:[9,15,5],state:27},{pos:[10,15,5],state:27},{pos:[11,15,5],state:27},{pos:[12,15,5],state:27},{pos:[13,15,5],state:27},{pos:[14,15,5],state:27},{pos:[0,15,6],state:27},{pos:[1,15,6],state:27},{pos:[2,15,6],state:27},{pos:[3,15,6],state:27},{pos:[4,15,6],state:27},{pos:[5,15,6],state:27},{pos:[6,15,6],state:27},{pos:[7,15,6],state:27},{pos:[8,15,6],state:27},{pos:[9,15,6],state:27},{pos:[10,15,6],state:27},{pos:[11,15,6],state:27},{pos:[12,15,6],state:27},{pos:[13,15,6],state:27},{pos:[14,15,6],state:27},{pos:[6,3,12],state:28},{pos:[7,3,12],state:18},{pos:[8,3,12],state:28},{pos:[7,3,0],state:28},{pos:[6,3,0],state:28},{pos:[8,3,0],state:28},{pos:[7,6,12],state:28},{pos:[8,6,12],state:28},{pos:[6,6,12],state:28}],entities:[]}