{
    DataVersion: 3465,
    size: [11, 10, 11],
    entities: [],
    blocks: [{pos:[0,0,0],state:1},{pos:[1,0,0],state:1},{pos:[2,0,0],state:1},{pos:[3,0,0],state:1},{pos:[4,0,0],state:2},{pos:[5,0,0],state:3},{pos:[6,0,0],state:3},{pos:[7,0,0],state:1},{pos:[8,0,0],state:1},{pos:[9,0,0],state:1},{pos:[10,0,0],state:3},{pos:[0,0,1],state:1},{pos:[1,0,1],state:2},{pos:[2,0,1],state:3},{pos:[3,0,1],state:2},{pos:[4,0,1],state:3},{pos:[5,0,1],state:1},{pos:[6,0,1],state:2},{pos:[7,0,1],state:4},{pos:[8,0,1],state:3},{pos:[9,0,1],state:1},{pos:[10,0,1],state:4},{pos:[0,0,2],state:3},{pos:[1,0,2],state:1},{pos:[2,0,2],state:5},{pos:[3,0,2],state:5},{pos:[4,0,2],state:5},{pos:[5,0,2],state:5},{pos:[6,0,2],state:5},{pos:[7,0,2],state:5},{pos:[8,0,2],state:5},{pos:[9,0,2],state:5},{pos:[10,0,2],state:1},{pos:[0,0,3],state:2},{pos:[1,0,3],state:1},{pos:[2,0,3],state:5},{pos:[3,0,3],state:5},{pos:[4,0,3],state:5},{pos:[5,0,3],state:5},{pos:[6,0,3],state:5},{pos:[7,0,3],state:5},{pos:[8,0,3],state:5},{pos:[9,0,3],state:5},{pos:[10,0,3],state:2},{pos:[0,0,4],state:4},{pos:[1,0,4],state:1},{pos:[2,0,4],state:5},{pos:[3,0,4],state:5},{pos:[4,0,4],state:5},{pos:[5,0,4],state:5},{pos:[6,0,4],state:5},{pos:[7,0,4],state:5},{pos:[8,0,4],state:5},{pos:[9,0,4],state:5},{pos:[10,0,4],state:4},{pos:[0,0,5],state:4},{pos:[1,0,5],state:1},{pos:[2,0,5],state:5},{pos:[3,0,5],state:5},{pos:[4,0,5],state:5},{pos:[5,0,5],state:5},{pos:[6,0,5],state:5},{pos:[7,0,5],state:5},{pos:[8,0,5],state:5},{pos:[9,0,5],state:5},{pos:[10,0,5],state:4},{pos:[0,0,6],state:2},{pos:[1,0,6],state:1},{pos:[2,0,6],state:5},{pos:[3,0,6],state:5},{pos:[4,0,6],state:5},{pos:[5,0,6],state:5},{pos:[6,0,6],state:5},{pos:[7,0,6],state:5},{pos:[8,0,6],state:5},{pos:[9,0,6],state:5},{pos:[10,0,6],state:2},{pos:[0,0,7],state:3},{pos:[1,0,7],state:1},{pos:[2,0,7],state:5},{pos:[3,0,7],state:5},{pos:[4,0,7],state:5},{pos:[5,0,7],state:5},{pos:[6,0,7],state:5},{pos:[7,0,7],state:5},{pos:[8,0,7],state:5},{pos:[9,0,7],state:5},{pos:[10,0,7],state:1},{pos:[0,0,8],state:1},{pos:[1,0,8],state:1},{pos:[2,0,8],state:4},{pos:[3,0,8],state:6},{pos:[6,0,8],state:6},{pos:[7,0,8],state:1},{pos:[8,0,8],state:1},{pos:[9,0,8],state:2},{pos:[10,0,8],state:1},{pos:[0,0,9],state:2},{pos:[1,0,9],state:2},{pos:[2,0,9],state:4},{pos:[3,0,9],state:6},{pos:[5,0,9],state:6},{pos:[6,0,9],state:6},{pos:[7,0,9],state:4},{pos:[8,0,9],state:3},{pos:[9,0,9],state:3},{pos:[10,0,9],state:3},{pos:[0,0,10],state:2},{pos:[1,0,10],state:2},{pos:[2,0,10],state:1},{pos:[3,0,10],state:3},{pos:[4,0,10],state:1},{pos:[5,0,10],state:1},{pos:[6,0,10],state:3},{pos:[7,0,10],state:1},{pos:[8,0,10],state:3},{pos:[9,0,10],state:1},{pos:[10,0,10],state:3},{pos:[4,1,0],state:1},{pos:[6,1,0],state:2},{pos:[8,1,0],state:3},{pos:[10,1,0],state:1},{pos:[2,1,1],state:1},{pos:[4,1,1],state:2},{pos:[6,1,1],state:3},{pos:[8,1,1],state:1},{pos:[10,1,1],state:2},{pos:[2,1,2],state:3},{pos:[4,1,2],state:5},{pos:[6,1,2],state:5},{pos:[8,1,2],state:5},{pos:[10,1,2],state:5},{pos:[2,1,3],state:2},{pos:[4,1,3],state:5},{pos:[2,1,4],state:4},{pos:[4,1,4],state:5},{pos:[2,1,5],state:4},{pos:[4,1,5],state:5},{pos:[2,1,6],state:2},{pos:[4,1,6],state:5},{pos:[2,1,7],state:3},{pos:[4,1,7],state:5},{pos:[6,1,7],state:5},{pos:[8,1,7],state:5},{pos:[10,1,7],state:5},{pos:[2,1,8],state:1},{pos:[4,1,8],state:1},{pos:[6,1,8],state:4},{pos:[8,1,8],state:7},{pos:[10,1,8],state:8},{pos:[2,1,9],state:2},{pos:[4,1,9],state:2},{pos:[6,1,9],state:4},{pos:[8,1,9],state:6},{pos:[10,1,9],state:6},{pos:[2,1,10],state:2},{pos:[4,1,10],state:2},{pos:[6,1,10],state:1},{pos:[8,1,10],state:3},{pos:[10,1,10],state:3},{pos:[2,2,2],state:3},{pos:[4,2,2],state:5},{pos:[6,2,2],state:9},{pos:[8,2,2],state:5},{pos:[10,2,2],state:9},{pos:[2,2,3],state:2},{pos:[4,2,3],state:5},{pos:[8,2,3],state:9},{pos:[2,2,4],state:4},{pos:[4,2,4],state:5},{pos:[6,2,4],state:9},{pos:[10,2,4],state:9},{pos:[2,2,5],state:4},{pos:[4,2,5],state:5},{pos:[8,2,5],state:9},{pos:[2,2,6],state:2},{pos:[4,2,6],state:5},{pos:[6,2,6],state:9},{pos:[10,2,6],state:9},{pos:[2,2,7],state:3},{pos:[4,2,7],state:5},{pos:[6,2,7],state:9},{pos:[8,2,7],state:5},{pos:[10,2,7],state:9},{pos:[2,2,8],state:1},{pos:[4,2,8],state:1},{pos:[6,2,8],state:4},{pos:[8,2,8],state:10},{pos:[10,2,8],state:11},{pos:[2,2,9],state:2},{pos:[4,2,9],state:2},{pos:[6,2,9],state:4},{pos:[8,2,9],state:2},{pos:[10,2,9],state:6},{pos:[2,2,10],state:2},{pos:[4,2,10],state:2},{pos:[6,2,10],state:1},{pos:[8,2,10],state:3},{pos:[10,2,10],state:3},{pos:[6,3,0],state:5},{pos:[8,3,0],state:5},{pos:[10,3,0],state:1},{pos:[4,3,1],state:5},{pos:[6,3,1],state:5},{pos:[8,3,1],state:1},{pos:[10,3,1],state:1},{pos:[2,3,2],state:5},{pos:[4,3,2],state:5},{pos:[6,3,2],state:5},{pos:[8,3,2],state:1},{pos:[10,3,2],state:1},{pos:[2,3,3],state:5},{pos:[4,3,3],state:5},{pos:[6,3,3],state:5},{pos:[8,3,3],state:5},{pos:[10,3,3],state:5},{pos:[0,3,4],state:5},{pos:[2,3,4],state:5},{pos:[4,3,4],state:5},{pos:[6,3,4],state:5},{pos:[8,3,4],state:5},{pos:[10,3,4],state:5},{pos:[0,3,5],state:5},{pos:[2,3,5],state:5},{pos:[4,3,5],state:5},{pos:[6,3,5],state:5},{pos:[8,3,5],state:5},{pos:[10,3,5],state:5},{pos:[0,3,6],state:5},{pos:[2,3,6],state:5},{pos:[4,3,6],state:5},{pos:[6,3,6],state:5},{pos:[8,3,6],state:5},{pos:[10,3,6],state:5},{pos:[2,3,7],state:5},{pos:[4,3,7],state:5},{pos:[6,3,7],state:5},{pos:[8,3,7],state:5},{pos:[10,3,7],state:5},{pos:[2,3,8],state:5},{pos:[4,3,8],state:12},{pos:[6,3,8],state:12},{pos:[8,3,8],state:12},{pos:[4,3,9],state:12},{pos:[6,3,9],state:12},{pos:[8,3,9],state:12},{pos:[10,3,9],state:13},{pos:[6,3,10],state:5},{pos:[8,3,10],state:5},{pos:[6,4,0],state:5},{pos:[8,4,0],state:9},{pos:[10,4,0],state:14},{pos:[4,4,1],state:5},{pos:[6,4,1],state:9},{pos:[8,4,1],state:14},{pos:[10,4,1],state:15},{pos:[2,4,2],state:5},{pos:[4,4,2],state:9},{pos:[6,4,2],state:5},{pos:[8,4,2],state:5},{pos:[10,4,2],state:5},{pos:[2,4,3],state:5},{pos:[4,4,3],state:5},{pos:[6,4,3],state:5},{pos:[8,4,3],state:16},{pos:[10,4,3],state:16},{pos:[0,4,4],state:5},{pos:[2,4,4],state:9},{pos:[4,4,4],state:5},{pos:[6,4,4],state:16},{pos:[8,4,4],state:16},{pos:[10,4,4],state:17},{pos:[0,4,5],state:5},{pos:[2,4,5],state:5},{pos:[4,4,5],state:16},{pos:[6,4,5],state:16},{pos:[8,4,5],state:16},{pos:[10,4,5],state:5},{pos:[0,4,6],state:5},{pos:[2,4,6],state:5},{pos:[4,4,6],state:5},{pos:[6,4,6],state:5},{pos:[8,4,6],state:5},{pos:[10,4,6],state:5},{pos:[2,4,7],state:5},{pos:[4,4,7],state:9},{pos:[6,4,7],state:5},{pos:[8,4,7],state:5},{pos:[10,4,7],state:5},{pos:[2,4,8],state:5},{pos:[4,4,8],state:5},{pos:[6,4,8],state:12},{pos:[8,4,8],state:12},{pos:[4,4,9],state:12},{pos:[6,4,9],state:12},{pos:[8,4,9],state:12},{pos:[10,4,9],state:13},{pos:[6,4,10],state:5},{pos:[8,4,10],state:5},{pos:[6,5,0],state:5},{pos:[8,5,0],state:9},{pos:[10,5,0],state:14},{pos:[4,5,1],state:5},{pos:[6,5,1],state:9},{pos:[8,5,1],state:14},{pos:[10,5,1],state:15},{pos:[2,5,2],state:5},{pos:[4,5,2],state:9},{pos:[6,5,2],state:5},{pos:[8,5,2],state:18},{pos:[10,5,2],state:5},{pos:[2,5,3],state:5},{pos:[4,5,3],state:5},{pos:[6,5,3],state:9},{pos:[8,5,3],state:16},{pos:[10,5,3],state:16},{pos:[0,5,4],state:5},{pos:[2,5,4],state:9},{pos:[4,5,4],state:5},{pos:[6,5,4],state:18},{pos:[10,5,4],state:19},{pos:[0,5,5],state:5},{pos:[2,5,5],state:5},{pos:[4,5,5],state:5},{pos:[6,5,5],state:16},{pos:[8,5,5],state:16},{pos:[10,5,5],state:5},{pos:[0,5,6],state:5},{pos:[2,5,6],state:5},{pos:[4,5,6],state:5},{pos:[6,5,6],state:5},{pos:[8,5,6],state:5},{pos:[10,5,6],state:5},{pos:[2,5,7],state:5},{pos:[4,5,7],state:9},{pos:[6,5,7],state:5},{pos:[8,5,7],state:5},{pos:[10,5,7],state:18},{pos:[2,5,8],state:5},{pos:[4,5,8],state:5},{pos:[6,5,8],state:9},{pos:[8,5,8],state:12},{pos:[10,5,8],state:20},{pos:[4,5,9],state:5},{pos:[6,5,9],state:9},{pos:[8,5,9],state:12},{pos:[10,5,9],state:12},{pos:[6,5,10],state:5},{pos:[8,5,10],state:5},{pos:[6,6,0],state:21},{pos:[8,6,0],state:22},{pos:[10,6,0],state:18},{pos:[4,6,1],state:21},{pos:[6,6,1],state:22},{pos:[8,6,1],state:5},{pos:[10,6,1],state:5},{pos:[2,6,2],state:23},{pos:[4,6,2],state:5},{pos:[6,6,2],state:5},{pos:[8,6,2],state:18},{pos:[10,6,2],state:5},{pos:[2,6,3],state:21},{pos:[4,6,3],state:5},{pos:[6,6,3],state:5},{pos:[8,6,3],state:5},{pos:[10,6,3],state:5},{pos:[0,6,4],state:21},{pos:[2,6,4],state:5},{pos:[4,6,4],state:5},{pos:[6,6,4],state:5},{pos:[8,6,4],state:5},{pos:[10,6,4],state:5},{pos:[0,6,5],state:5},{pos:[2,6,5],state:5},{pos:[4,6,5],state:5},{pos:[6,6,5],state:5},{pos:[8,6,5],state:5},{pos:[10,6,5],state:18},{pos:[0,6,6],state:23},{pos:[2,6,6],state:5},{pos:[4,6,6],state:5},{pos:[6,6,6],state:5},{pos:[8,6,6],state:5},{pos:[10,6,6],state:5},{pos:[2,6,7],state:21},{pos:[4,6,7],state:5},{pos:[6,6,7],state:5},{pos:[8,6,7],state:5},{pos:[10,6,7],state:5},{pos:[4,6,8],state:23},{pos:[6,6,8],state:22},{pos:[8,6,8],state:18},{pos:[10,6,8],state:22},{pos:[6,6,9],state:21},{pos:[8,6,9],state:22},{pos:[10,6,9],state:22},{pos:[4,7,0],state:1},{pos:[6,7,0],state:1},{pos:[8,7,0],state:1},{pos:[10,7,0],state:2},{pos:[2,7,1],state:1},{pos:[4,7,1],state:2},{pos:[6,7,1],state:3},{pos:[8,7,1],state:1},{pos:[10,7,1],state:3},{pos:[2,7,2],state:1},{pos:[4,7,2],state:3},{pos:[6,7,2],state:1},{pos:[8,7,2],state:2},{pos:[10,7,2],state:3},{pos:[2,7,3],state:2},{pos:[4,7,3],state:3},{pos:[6,7,3],state:1},{pos:[8,7,3],state:3},{pos:[10,7,3],state:1},{pos:[2,7,4],state:1},{pos:[4,7,4],state:3},{pos:[6,7,4],state:1},{pos:[8,7,4],state:2},{pos:[10,7,4],state:3},{pos:[2,7,5],state:2},{pos:[4,7,5],state:3},{pos:[6,7,5],state:1},{pos:[8,7,5],state:3},{pos:[10,7,5],state:1},{pos:[2,7,6],state:1},{pos:[4,7,6],state:3},{pos:[6,7,6],state:1},{pos:[8,7,6],state:2},{pos:[10,7,6],state:3},{pos:[2,7,7],state:1},{pos:[4,7,7],state:2},{pos:[6,7,7],state:3},{pos:[8,7,7],state:1},{pos:[10,7,7],state:3},{pos:[2,7,8],state:1},{pos:[4,7,8],state:1},{pos:[6,7,8],state:1},{pos:[8,7,8],state:2},{pos:[10,7,8],state:3},{pos:[4,8,1],state:2},{pos:[6,8,1],state:3},{pos:[8,8,1],state:1},{pos:[10,8,1],state:3},{pos:[2,8,2],state:2},{pos:[4,8,2],state:3},{pos:[6,8,2],state:1},{pos:[8,8,2],state:3},{pos:[10,8,2],state:3},{pos:[2,8,3],state:2},{pos:[4,8,3],state:3},{pos:[6,8,3],state:1},{pos:[8,8,3],state:3},{pos:[10,8,3],state:3},{pos:[2,8,4],state:2},{pos:[4,8,4],state:3},{pos:[6,8,4],state:1},{pos:[8,8,4],state:3},{pos:[10,8,4],state:3},{pos:[2,8,5],state:2},{pos:[4,8,5],state:3},{pos:[6,8,5],state:3},{pos:[8,8,5],state:3},{pos:[10,8,5],state:3},{pos:[2,8,6],state:2},{pos:[4,8,6],state:3},{pos:[6,8,6],state:3},{pos:[8,8,6],state:2},{pos:[10,8,6],state:3},{pos:[4,8,7],state:2},{pos:[6,8,7],state:3},{pos:[8,8,7],state:1},{pos:[10,8,7],state:3},{pos:[6,9,2],state:2},{pos:[8,9,2],state:3},{pos:[10,9,2],state:3},{pos:[6,9,3],state:3},{pos:[8,9,3],state:1},{pos:[10,9,3],state:3},{pos:[6,9,4],state:3},{pos:[8,9,4],state:3},{pos:[10,9,4],state:3},{pos:[6,9,5],state:2},{pos:[8,9,5],state:3},{pos:[10,9,5],state:1},{pos:[6,9,6],state:2},{pos:[8,9,6],state:3},{pos:[10,9,6],state:3}],
    palette: [{Name:"minecraft:air"},{Name:"minecraft:coarse_dirt"},{Name:"minecraft:moss_block"},{Name:"minecraft:grass_block"},{Name:"minecraft:mud_bricks"},{Name:"minecraft:oak_planks"},{Name:"minecraft:path_block"},{Name:"minecraft:spruce_door",Properties:{facing:"south",half:"lower",open:"false",hinge:"left"}},{Name:"minecraft:spruce_door",Properties:{facing:"south",half:"lower",open:"false",hinge:"right"}},{Name:"minecraft:stripped_spruce_log",Properties:{axis:"y"}},{Name:"minecraft:spruce_door",Properties:{facing:"south",half:"upper",open:"false",hinge:"left"}},{Name:"minecraft:spruce_door",Properties:{facing:"south",half:"upper",open:"false",hinge:"right"}},{Name:"minecraft:packed_mud"},{Name:"minecraft:chest",Properties:{facing:"south"}},{Name:"minecraft:stone_bricks"},{Name:"minecraft:mossy_stone_bricks"},{Name:"minecraft:spruce_slab",Properties:{type:"bottom"}},{Name:"minecraft:oak_pressure_plate"},{Name:"minecraft:shroomlight"},{Name:"minecraft:candle"},{Name:"minecraft:brown_wool"},{Name:"minecraft:stripped_spruce_log",Properties:{axis:"x"}},{Name:"minecraft:spruce_slab",Properties:{type:"top"}},{Name:"minecraft:stripped_spruce_log",Properties:{axis:"z"}}]
}