{DataVersion:3465,size:[16,16,16],palette:[{Name:"minecraft:air"},{Name:"minecraft:grass_block"},{Name:"minecraft:dirt"},{Name:"minecraft:coarse_dirt"},{Name:"minecraft:cobblestone"},{Name:"minecraft:spruce_planks"},{Name:"minecraft:stripped_oak_log"},{Name:"minecraft:spruce_log",Properties:{axis:"y"}},{Name:"minecraft:lime_terracotta"},{Name:"minecraft:spruce_stairs",Properties:{facing:"east",half:"bottom",shape:"straight"}},{Name:"minecraft:spruce_stairs",Properties:{facing:"west",half:"bottom",shape:"straight"}},{Name:"minecraft:spruce_stairs",Properties:{facing:"east",half:"top",shape:"straight"}},{Name:"minecraft:spruce_stairs",Properties:{facing:"west",half:"top",shape:"straight"}},{Name:"minecraft:glass_pane"},{Name:"minecraft:oak_trapdoor",Properties:{facing:"east",half:"bottom",open:"true"}},{Name:"minecraft:oak_trapdoor",Properties:{facing:"west",half:"bottom",open:"true"}},{Name:"minecraft:stone_bricks"},{Name:"minecraft:campfire",Properties:{lit:"true"}},{Name:"minecraft:iron_bars"},{Name:"minecraft:bookshelf"},{Name:"minecraft:red_carpet"},{Name:"minecraft:oak_fence"},{Name:"minecraft:oak_pressure_plate"},{Name:"minecraft:lantern",Properties:{hanging:"true"}},{Name:"minecraft:poppy"},{Name:"minecraft:azure_bluet"},{Name:"minecraft:oak_leaves",Properties:{persistent:"true"}},{Name:"minecraft:spruce_slab",Properties:{type:"bottom"}},{Name:"minecraft:spruce_slab",Properties:{type:"top"}},{Name:"minecraft:spruce_log",Properties:{axis:"x"}},{Name:"minecraft:oak_stairs",Properties:{facing:"west"}},{Name:"minecraft:oak_stairs",Properties:{facing:"east"}},{Name:"minecraft:flower_pot"}],blocks:[{pos:[0,0,0],state:1},{pos:[1,0,0],state:1},{pos:[2,0,0],state:1},{pos:[3,0,0],state:1},{pos:[4,0,0],state:1},{pos:[5,0,0],state:1},{pos:[6,0,0],state:26},{pos:[7,0,0],state:3},{pos:[8,0,0],state:4},{pos:[9,0,0],state:1},{pos:[10,0,0],state:26},{pos:[11,0,0],state:1},{pos:[12,0,0],state:1},{pos:[13,0,0],state:1},{pos:[14,0,0],state:1},{pos:[15,0,0],state:1},{pos:[0,0,1],state:1},{pos:[1,0,1],state:1},{pos:[2,0,1],state:1},{pos:[3,0,1],state:1},{pos:[4,0,1],state:1},{pos:[5,0,1],state:1},{pos:[6,0,1],state:26},{pos:[7,0,1],state:4},{pos:[8,0,1],state:3},{pos:[9,0,1],state:4},{pos:[10,0,1],state:26},{pos:[11,0,1],state:1},{pos:[12,0,1],state:1},{pos:[13,0,1],state:1},{pos:[14,0,1],state:1},{pos:[15,0,1],state:1},{pos:[0,0,2],state:1},{pos:[1,0,2],state:1},{pos:[2,0,2],state:26},{pos:[3,0,2],state:1},{pos:[4,0,2],state:1},{pos:[5,0,2],state:24},{pos:[6,0,2],state:1},{pos:[7,0,2],state:4},{pos:[8,0,2],state:4},{pos:[9,0,2],state:3},{pos:[10,0,2],state:25},{pos:[11,0,2],state:1},{pos:[12,0,2],state:1},{pos:[13,0,2],state:1},{pos:[14,0,2],state:1},{pos:[15,0,2],state:1},{pos:[0,0,3],state:1},{pos:[1,0,3],state:1},{pos:[2,0,3],state:26},{pos:[3,0,3],state:1},{pos:[4,0,3],state:1},{pos:[5,0,3],state:1},{pos:[6,0,3],state:3},{pos:[7,0,3],state:3},{pos:[8,0,3],state:4},{pos:[9,0,3],state:1},{pos:[10,0,3],state:1},{pos:[11,0,3],state:1},{pos:[12,0,3],state:1},{pos:[13,0,3],state:1},{pos:[14,0,3],state:1},{pos:[15,0,3],state:1},{pos:[0,0,4],state:1},{pos:[1,0,4],state:1},{pos:[2,0,4],state:1},{pos:[3,0,4],state:7},{pos:[4,0,4],state:6},{pos:[5,0,4],state:6},{pos:[6,0,4],state:6},{pos:[7,0,4],state:27},{pos:[8,0,4],state:4},{pos:[9,0,4],state:27},{pos:[10,0,4],state:6},{pos:[11,0,4],state:6},{pos:[12,0,4],state:6},{pos:[13,0,4],state:7},{pos:[14,0,4],state:1},{pos:[15,0,4],state:1},{pos:[0,0,5],state:1},{pos:[1,0,5],state:1},{pos:[2,0,5],state:1},{pos:[3,0,5],state:7},{pos:[4,0,5],state:5},{pos:[5,0,5],state:5},{pos:[6,0,5],state:5},{pos:[7,0,5],state:5},{pos:[8,0,5],state:5},{pos:[9,0,5],state:5},{pos:[10,0,5],state:5},{pos:[11,0,5],state:5},{pos:[12,0,5],state:5},{pos:[13,0,5],state:7},{pos:[14,0,5],state:1},{pos:[15,0,5],state:1},{pos:[3,0,6],state:7},{pos:[4,0,6],state:5},{pos:[5,0,6],state:5},{pos:[6,0,6],state:5},{pos:[7,0,6],state:5},{pos:[8,0,6],state:5},{pos:[9,0,6],state:5},{pos:[10,0,6],state:5},{pos:[11,0,6],state:5},{pos:[12,0,6],state:5},{pos:[13,0,6],state:7},{pos:[3,0,7],state:7},{pos:[4,0,7],state:5},{pos:[5,0,7],state:5},{pos:[6,0,7],state:5},{pos:[7,0,7],state:5},{pos:[8,0,7],state:5},{pos:[9,0,7],state:5},{pos:[10,0,7],state:5},{pos:[11,0,7],state:5},{pos:[12,0,7],state:5},{pos:[13,0,7],state:7},{pos:[3,0,8],state:7},{pos:[4,0,8],state:5},{pos:[5,0,8],state:5},{pos:[6,0,8],state:5},{pos:[7,0,8],state:5},{pos:[8,0,8],state:5},{pos:[9,0,8],state:5},{pos:[10,0,8],state:5},{pos:[11,0,8],state:5},{pos:[12,0,8],state:5},{pos:[13,0,8],state:7},{pos:[3,0,9],state:7},{pos:[4,0,9],state:5},{pos:[5,0,9],state:5},{pos:[6,0,9],state:5},{pos:[7,0,9],state:5},{pos:[8,0,9],state:5},{pos:[9,0,9],state:5},{pos:[10,0,9],state:5},{pos:[11,0,9],state:5},{pos:[12,0,9],state:5},{pos:[13,0,9],state:7},{pos:[3,0,10],state:7},{pos:[4,0,10],state:5},{pos:[5,0,10],state:5},{pos:[6,0,10],state:5},{pos:[7,0,10],state:5},{pos:[8,0,10],state:5},{pos:[9,0,10],state:5},{pos:[10,0,10],state:5},{pos:[11,0,10],state:5},{pos:[12,0,10],state:5},{pos:[13,0,10],state:7},{pos:[3,0,11],state:7},{pos:[4,0,11],state:5},{pos:[5,0,11],state:5},{pos:[6,0,11],state:5},{pos:[7,0,11],state:5},{pos:[8,0,11],state:5},{pos:[9,0,11],state:5},{pos:[10,0,11],state:5},{pos:[11,0,11],state:5},{pos:[12,0,11],state:5},{pos:[13,0,11],state:7},{pos:[3,0,12],state:7},{pos:[4,0,12],state:5},{pos:[5,0,12],state:5},{pos:[6,0,12],state:5},{pos:[7,0,12],state:5},{pos:[8,0,12],state:5},{pos:[9,0,12],state:5},{pos:[10,0,12],state:5},{pos:[11,0,12],state:5},{pos:[12,0,12],state:5},{pos:[13,0,12],state:7},{pos:[3,0,13],state:7},{pos:[4,0,13],state:5},{pos:[5,0,13],state:5},{pos:[6,0,13],state:5},{pos:[7,0,13],state:5},{pos:[8,0,13],state:5},{pos:[9,0,13],state:5},{pos:[10,0,13],state:5},{pos:[11,0,13],state:5},{pos:[12,0,13],state:5},{pos:[13,0,13],state:7},{pos:[3,1,4],state:7},{pos:[4,1,4],state:6},{pos:[5,1,4],state:6},{pos:[6,1,4],state:6},{pos:[7,1,4],state:9},{pos:[8,1,4],state:8},{pos:[9,1,4],state:10},{pos:[10,1,4],state:6},{pos:[11,1,4],state:6},{pos:[12,1,4],state:6},{pos:[13,1,4],state:7},{pos:[3,1,5],state:7},{pos:[4,1,5],state:19},{pos:[5,1,5],state:19},{pos:[6,1,5],state:5},{pos:[7,1,5],state:20},{pos:[8,1,5],state:20},{pos:[9,1,5],state:20},{pos:[10,1,5],state:5},{pos:[11,1,5],state:5},{pos:[12,1,5],state:30},{pos:[13,1,5],state:7},{pos:[3,1,6],state:7},{pos:[4,1,6],state:5},{pos:[12,1,6],state:5},{pos:[13,1,6],state:7},{pos:[3,1,7],state:7},{pos:[4,1,7],state:5},{pos:[8,1,7],state:30},{pos:[12,1,7],state:5},{pos:[13,1,7],state:7},{pos:[3,1,8],state:7},{pos:[4,1,8],state:5},{pos:[7,1,8],state:20},{pos:[8,1,8],state:20},{pos:[9,1,8],state:20},{pos:[12,1,8],state:5},{pos:[13,1,8],state:7},{pos:[3,1,9],state:7},{pos:[4,1,9],state:5},{pos:[7,1,9],state:20},{pos:[8,1,9],state:21},{pos:[9,1,9],state:20},{pos:[12,1,9],state:5},{pos:[13,1,9],state:7},{pos:[3,1,10],state:7},{pos:[4,1,10],state:5},{pos:[7,1,10],state:20},{pos:[8,1,10],state:20},{pos:[9,1,10],state:20},{pos:[12,1,10],state:16},{pos:[13,1,10],state:7},{pos:[3,1,11],state:7},{pos:[4,1,11],state:5},{pos:[5,1,11],state:18},{pos:[11,1,11],state:18},{pos:[12,1,11],state:16},{pos:[13,1,11],state:7},{pos:[3,1,12],state:7},{pos:[4,1,12],state:5},{pos:[5,1,12],state:18},{pos:[6,1,12],state:18},{pos:[7,1,12],state:18},{pos:[8,1,12],state:18},{pos:[9,1,12],state:18},{pos:[10,1,12],state:18},{pos:[11,1,12],state:18},{pos:[12,1,12],state:16},{pos:[13,1,12],state:7},{pos:[3,1,13],state:7},{pos:[4,1,13],state:5},{pos:[5,1,13],state:5},{pos:[6,1,13],state:5},{pos:[7,1,13],state:5},{pos:[8,1,13],state:5},{pos:[9,1,13],state:5},{pos:[10,1,13],state:5},{pos:[11,1,13],state:5},{pos:[12,1,13],state:16},{pos:[13,1,13],state:7},{pos:[3,2,4],state:7},{pos:[4,2,4],state:14},{pos:[5,2,4],state:6},{pos:[6,2,4],state:6},{pos:[7,2,4],state:8},{pos:[8,2,4],state:8},{pos:[9,2,4],state:8},{pos:[10,2,4],state:6},{pos:[11,2,4],state:6},{pos:[12,2,4],state:14},{pos:[13,2,4],state:7},{pos:[2,2,4],state:15},{pos:[5,2,3],state:16},{pos:[11,2,3],state:15},{pos:[3,2,3],state:26},{pos:[13,2,3],state:26},{pos:[3,2,5],state:7},{pos:[4,2,5],state:32},{pos:[12,2,5],state:32},{pos:[13,2,5],state:7},{pos:[3,2,6],state:7},{pos:[13,2,6],state:7},{pos:[3,2,7],state:7},{pos:[13,2,7],state:7},{pos:[3,2,8],state:7},{pos:[7,2,8],state:30},{pos:[9,2,8],state:31},{pos:[13,2,8],state:7},{pos:[3,2,9],state:7},{pos:[7,2,9],state:21},{pos:[8,2,9],state:22},{pos:[9,2,9],state:21},{pos:[13,2,9],state:7},{pos:[3,2,10],state:7},{pos:[7,2,10],state:30},{pos:[9,2,10],state:31},{pos:[12,2,10],state:17},{pos:[13,2,10],state:7},{pos:[3,2,11],state:7},{pos:[4,2,11],state:5},{pos:[5,2,11],state:18},{pos:[11,2,11],state:18},{pos:[12,2,11],state:16},{pos:[13,2,11],state:7},{pos:[3,2,12],state:7},{pos:[4,2,12],state:5},{pos:[5,2,12],state:18},{pos:[6,2,12],state:18},{pos:[7,2,12],state:18},{pos:[8,2,12],state:18},{pos:[9,2,12],state:18},{pos:[10,2,12],state:18},{pos:[11,2,12],state:18},{pos:[12,2,12],state:16},{pos:[13,2,12],state:7},{pos:[3,2,13],state:7},{pos:[4,2,13],state:5},{pos:[5,2,13],state:5},{pos:[6,2,13],state:5},{pos:[7,2,13],state:5},{pos:[8,2,13],state:5},{pos:[9,2,13],state:5},{pos:[10,2,13],state:5},{pos:[11,2,13],state:5},{pos:[12,2,13],state:16},{pos:[13,2,13],state:7},{pos:[3,3,4],state:7},{pos:[4,3,4],state:6},{pos:[5,3,4],state:6},{pos:[6,3,4],state:6},{pos:[7,3,4],state:11},{pos:[8,3,4],state:8},{pos:[9,3,4],state:12},{pos:[10,3,4],state:6},{pos:[11,3,4],state:6},{pos:[12,3,4],state:6},{pos:[13,3,4],state:7},{pos:[3,3,5],state:7},{pos:[4,3,5],state:5},{pos:[12,3,5],state:5},{pos:[13,3,5],state:7},{pos:[3,3,6],state:7},{pos:[13,3,6],state:7},{pos:[3,3,7],state:7},{pos:[13,3,7],state:7},{pos:[3,3,8],state:7},{pos:[13,3,8],state:7},{pos:[3,3,9],state:7},{pos:[13,3,9],state:7},{pos:[3,3,10],state:7},{pos:[12,3,10],state:18},{pos:[13,3,10],state:7},{pos:[3,3,11],state:7},{pos:[4,3,11],state:5},{pos:[5,3,11],state:18},{pos:[11,3,11],state:18},{pos:[12,3,11],state:16},{pos:[13,3,11],state:7},{pos:[3,3,12],state:7},{pos:[4,3,12],state:5},{pos:[5,3,12],state:18},{pos:[6,3,12],state:18},{pos:[7,3,12],state:18},{pos:[8,3,12],state:18},{pos:[9,3,12],state:18},{pos:[10,3,12],state:18},{pos:[11,3,12],state:18},{pos:[12,3,12],state:16},{pos:[13,3,12],state:7},{pos:[3,3,13],state:7},{pos:[4,3,13],state:5},{pos:[5,3,13],state:5},{pos:[6,3,13],state:5},{pos:[7,3,13],state:5},{pos:[8,3,13],state:5},{pos:[9,3,13],state:5},{pos:[10,3,13],state:5},{pos:[11,3,13],state:5},{pos:[12,3,13],state:16},{pos:[13,3,13],state:7},{pos:[3,4,4],state:7},{pos:[4,4,4],state:7},{pos:[5,4,4],state:6},{pos:[6,4,4],state:6},{pos:[7,4,4],state:6},{pos:[8,4,4],state:6},{pos:[9,4,4],state:6},{pos:[10,4,4],state:6},{pos:[11,4,4],state:6},{pos:[12,4,4],state:7},{pos:[13,4,4],state:7},{pos:[3,4,5],state:7},{pos:[4,4,5],state:5},{pos:[12,4,5],state:5},{pos:[13,4,5],state:7},{pos:[3,4,6],state:7},{pos:[13,4,6],state:7},{pos:[3,4,7],state:7},{pos:[13,4,7],state:7},{pos:[3,4,8],state:7},{pos:[13,4,8],state:7},{pos:[3,4,9],state:7},{pos:[4,4,9],state:29},{pos:[5,4,9],state:29},{pos:[6,4,9],state:29},{pos:[7,4,9],state:29},{pos:[8,4,9],state:23},{pos:[9,4,9],state:29},{pos:[10,4,9],state:29},{pos:[11,4,9],state:29},{pos:[12,4,9],state:29},{pos:[13,4,9],state:7},{pos:[8,3,9],state:23},{pos:[3,4,10],state:7},{pos:[12,4,10],state:16},{pos:[13,4,10],state:7},{pos:[3,4,11],state:7},{pos:[4,4,11],state:5},{pos:[5,4,11],state:5},{pos:[11,4,11],state:5},{pos:[12,4,11],state:16},{pos:[13,4,11],state:7},{pos:[3,4,12],state:7},{pos:[4,4,12],state:5},{pos:[5,4,12],state:5},{pos:[6,4,12],state:5},{pos:[7,4,12],state:5},{pos:[8,4,12],state:5},{pos:[9,4,12],state:5},{pos:[10,4,12],state:5},{pos:[11,4,12],state:5},{pos:[12,4,12],state:16},{pos:[13,4,12],state:7},{pos:[3,4,13],state:7},{pos:[4,4,13],state:5},{pos:[5,4,13],state:5},{pos:[6,4,13],state:5},{pos:[7,4,13],state:5},{pos:[8,4,13],state:5},{pos:[9,4,13],state:5},{pos:[10,4,13],state:5},{pos:[11,4,13],state:5},{pos:[12,4,13],state:16},{pos:[13,4,13],state:7},{pos:[4,5,5],state:27},{pos:[5,5,5],state:27},{pos:[6,5,5],state:27},{pos:[7,5,5],state:27},{pos:[8,5,5],state:27},{pos:[9,5,5],state:27},{pos:[10,5,5],state:27},{pos:[11,5,5],state:27},{pos:[12,5,5],state:27},{pos:[4,5,6],state:27},{pos:[5,5,6],state:27},{pos:[6,5,6],state:27},{pos:[7,5,6],state:27},{pos:[8,5,6],state:27},{pos:[9,5,6],state:27},{pos:[10,5,6],state:27},{pos:[11,5,6],state:27},{pos:[12,5,6],state:27},{pos:[4,5,7],state:27},{pos:[5,5,7],state:27},{pos:[6,5,7],state:27},{pos:[7,5,7],state:27},{pos:[8,5,7],state:27},{pos:[9,5,7],state:27},{pos:[10,5,7],state:27},{pos:[11,5,7],state:27},{pos:[12,5,7],state:27},{pos:[4,5,8],state:27},{pos:[5,5,8],state:27},{pos:[6,5,8],state:27},{pos:[7,5,8],state:27},{pos:[8,5,8],state:27},{pos:[9,5,8],state:27},{pos:[10,5,8],state:27},{pos:[11,5,8],state:27},{pos:[12,5,8],state:27},{pos:[4,5,9],state:27},{pos:[5,5,9],state:27},{pos:[6,5,9],state:27},{pos:[7,5,9],state:27},{pos:[8,5,9],state:27},{pos:[9,5,9],state:27},{pos:[10,5,9],state:27},{pos:[11,5,9],state:27},{pos:[12,5,9],state:27},{pos:[4,5,10],state:27},{pos:[5,5,10],state:27},{pos:[6,5,10],state:27},{pos:[7,5,10],state:27},{pos:[8,5,10],state:27},{pos:[9,5,10],state:27},{pos:[10,5,10],state:27},{pos:[11,5,10],state:27},{pos:[12,5,10],state:16},{pos:[4,5,11],state:27},{pos:[5,5,11],state:27},{pos:[6,5,11],state:27},{pos:[7,5,11],state:27},{pos:[8,5,11],state:27},{pos:[9,5,11],state:27},{pos:[10,5,11],state:27},{pos:[11,5,11],state:27},{pos:[12,5,11],state:16},{pos:[4,5,12],state:27},{pos:[5,5,12],state:27},{pos:[6,5,12],state:27},{pos:[7,5,12],state:27},{pos:[8,5,12],state:27},{pos:[9,5,12],state:27},{pos:[10,5,12],state:27},{pos:[11,5,12],state:27},{pos:[12,5,12],state:16},{pos:[4,5,13],state:27},{pos:[5,5,13],state:27},{pos:[6,5,13],state:27},{pos:[7,5,13],state:27},{pos:[8,5,13],state:27},{pos:[9,5,13],state:27},{pos:[10,5,13],state:27},{pos:[11,5,13],state:27},{pos:[12,5,13],state:16},{pos:[12,6,10],state:16},{pos:[12,6,11],state:16},{pos:[12,6,12],state:16},{pos:[12,6,13],state:16},{pos:[12,7,10],state:16},{pos:[12,7,11],state:16},{pos:[12,7,12],state:16},{pos:[12,7,13],state:16},{pos:[0,1,6],state:1},{pos:[1,1,6],state:1},{pos:[2,1,6],state:1},{pos:[14,1,6],state:1},{pos:[15,1,6],state:1},{pos:[0,2,7],state:1},{pos:[1,2,7],state:1},{pos:[2,2,7],state:1},{pos:[14,2,7],state:1},{pos:[15,2,7],state:1},{pos:[1,3,8],state:1},{pos:[2,3,8],state:1},{pos:[14,3,8],state:1},{pos:[15,3,8],state:1},{pos:[3,5,4],state:1},{pos:[4,5,4],state:1},{pos:[5,5,4],state:1},{pos:[6,5,4],state:1},{pos:[7,5,4],state:1},{pos:[8,5,4],state:1},{pos:[9,5,4],state:1},{pos:[10,5,4],state:1},{pos:[11,5,4],state:1},{pos:[12,5,4],state:1},{pos:[13,5,4],state:1},{pos:[3,6,5],state:1},{pos:[4,6,5],state:1},{pos:[5,6,5],state:1},{pos:[6,6,5],state:1},{pos:[7,6,5],state:1},{pos:[8,6,5],state:1},{pos:[9,6,5],state:1},{pos:[10,6,5],state:1},{pos:[11,6,5],state:1},{pos:[12,6,5],state:1},{pos:[13,6,5],state:1},{pos:[2,3,5],state:24},{pos:[14,3,5],state:24},{pos:[5,4,9],state:23},{pos:[11,4,9],state:23},{pos:[2,0,14],state:1},{pos:[14,0,14],state:1},{pos:[6,5,3],state:26},{pos:[10,5,3],state:26},{pos:[7,5,3],state:28},{pos:[9,5,3],state:28},{pos:[8,5,3],state:28}],entities:[]}