{DataVersion:3465,size:[10,11,10],palette:[{Name:"minecraft:air"},{Name:"minecraft:stone_bricks"},{Name:"minecraft:oak_planks"},{Name:"minecraft:oak_door",Properties:{facing:"south",half:"lower",open:"false",hinge:"right"}},{Name:"minecraft:oak_door",Properties:{facing:"south",half:"upper",open:"false",hinge:"right"}},{Name:"minecraft:glass_pane"},{Name:"minecraft:dark_oak_stairs",Properties:{facing:"east",half:"bottom",shape:"straight"}},{Name:"minecraft:dark_oak_stairs",Properties:{facing:"west",half:"bottom",shape:"straight"}},{Name:"minecraft:dark_oak_stairs",Properties:{facing:"east",half:"top",shape:"straight"}},{Name:"minecraft:dark_oak_stairs",Properties:{facing:"west",half:"top",shape:"straight"}},{Name:"minecraft:ladder",Properties:{facing:"north"}}],blocks:[{pos:[0,0,0],state:1},{pos:[0,0,1],state:1},{pos:[0,0,2],state:1},{pos:[0,0,3],state:1},{pos:[0,0,4],state:1},{pos:[0,0,5],state:1},{pos:[0,0,6],state:1},{pos:[0,0,7],state:1},{pos:[0,0,8],state:1},{pos:[0,0,9],state:1},{pos:[1,0,0],state:1},{pos:[1,0,1],state:1},{pos:[1,0,2],state:1},{pos:[1,0,3],state:1},{pos:[1,0,4],state:1},{pos:[1,0,5],state:1},{pos:[1,0,6],state:1},{pos:[1,0,7],state:1},{pos:[1,0,8],state:1},{pos:[1,0,9],state:1},{pos:[2,0,0],state:1},{pos:[2,0,1],state:1},{pos:[2,0,2],state:1},{pos:[2,0,3],state:1},{pos:[2,0,4],state:1},{pos:[2,0,5],state:1},{pos:[2,0,6],state:1},{pos:[2,0,7],state:1},{pos:[2,0,8],state:1},{pos:[2,0,9],state:1},{pos:[3,0,0],state:1},{pos:[3,0,1],state:1},{pos:[3,0,2],state:1},{pos:[3,0,3],state:1},{pos:[3,0,4],state:1},{pos:[3,0,5],state:1},{pos:[3,0,6],state:1},{pos:[3,0,7],state:1},{pos:[3,0,8],state:1},{pos:[3,0,9],state:1},{pos:[4,0,0],state:1},{pos:[4,0,1],state:1},{pos:[4,0,2],state:1},{pos:[4,0,3],state:1},{pos:[4,0,4],state:1},{pos:[4,0,5],state:1},{pos:[4,0,6],state:1},{pos:[4,0,7],state:1},{pos:[4,0,8],state:1},{pos:[4,0,9],state:1},{pos:[5,0,0],state:1},{pos:[5,0,1],state:1},{pos:[5,0,2],state:1},{pos:[5,0,3],state:1},{pos:[5,0,4],state:1},{pos:[5,0,5],state:1},{pos:[5,0,6],state:1},{pos:[5,0,7],state:1},{pos:[5,0,8],state:1},{pos:[5,0,9],state:1},{pos:[6,0,0],state:1},{pos:[6,0,1],state:1},{pos:[6,0,2],state:1},{pos:[6,0,3],state:1},{pos:[6,0,4],state:1},{pos:[6,0,5],state:1},{pos:[6,0,6],state:1},{pos:[6,0,7],state:1},{pos:[6,0,8],state:1},{pos:[6,0,9],state:1},{pos:[7,0,0],state:1},{pos:[7,0,1],state:1},{pos:[7,0,2],state:1},{pos:[7,0,3],state:1},{pos:[7,0,4],state:1},{pos:[7,0,5],state:1},{pos:[7,0,6],state:1},{pos:[7,0,7],state:1},{pos:[7,0,8],state:1},{pos:[7,0,9],state:1},{pos:[8,0,0],state:1},{pos:[8,0,1],state:1},{pos:[8,0,2],state:1},{pos:[8,0,3],state:1},{pos:[8,0,4],state:1},{pos:[8,0,5],state:1},{pos:[8,0,6],state:1},{pos:[8,0,7],state:1},{pos:[8,0,8],state:1},{pos:[8,0,9],state:1},{pos:[9,0,0],state:1},{pos:[9,0,1],state:1},{pos:[9,0,2],state:1},{pos:[9,0,3],state:1},{pos:[9,0,4],state:1},{pos:[9,0,5],state:1},{pos:[9,0,6],state:1},{pos:[9,0,7],state:1},{pos:[9,0,8],state:1},{pos:[9,0,9],state:1},{pos:[0,1,0],state:2},{pos:[0,1,1],state:2},{pos:[0,1,2],state:2},{pos:[0,1,3],state:2},{pos:[0,1,4],state:2},{pos:[0,1,5],state:2},{pos:[0,1,6],state:2},{pos:[0,1,7],state:2},{pos:[0,1,8],state:2},{pos:[0,1,9],state:2},{pos:[1,1,0],state:2},{pos:[1,1,9],state:2},{pos:[2,1,0],state:2},{pos:[2,1,9],state:2},{pos:[3,1,0],state:2},{pos:[3,1,9],state:2},{pos:[4,1,0],state:3},{pos:[4,1,9],state:2},{pos:[5,1,0],state:2},{pos:[5,1,1],state:10},{pos:[5,1,9],state:2},{pos:[6,1,0],state:2},{pos:[6,1,9],state:2},{pos:[7,1,0],state:2},{pos:[7,1,9],state:2},{pos:[8,1,0],state:2},{pos:[8,1,9],state:2},{pos:[9,1,0],state:2},{pos:[9,1,1],state:2},{pos:[9,1,2],state:2},{pos:[9,1,3],state:2},{pos:[9,1,4],state:2},{pos:[9,1,5],state:2},{pos:[9,1,6],state:2},{pos:[9,1,7],state:2},{pos:[9,1,8],state:2},{pos:[9,1,9],state:2},{pos:[0,2,0],state:2},{pos:[0,2,1],state:2},{pos:[0,2,2],state:5},{pos:[0,2,3],state:2},{pos:[0,2,4],state:2},{pos:[0,2,5],state:2},{pos:[0,2,6],state:2},{pos:[0,2,7],state:5},{pos:[0,2,8],state:2},{pos:[0,2,9],state:2},{pos:[1,2,0],state:5},{pos:[1,2,9],state:5},{pos:[2,2,0],state:2},{pos:[2,2,9],state:2},{pos:[3,2,0],state:2},{pos:[3,2,9],state:2},{pos:[4,2,0],state:4},{pos:[4,2,9],state:2},{pos:[5,2,0],state:2},{pos:[5,2,1],state:10},{pos:[5,2,9],state:2},{pos:[6,2,0],state:2},{pos:[6,2,9],state:2},{pos:[7,2,0],state:2},{pos:[7,2,9],state:2},{pos:[8,2,0],state:5},{pos:[8,2,9],state:5},{pos:[9,2,0],state:2},{pos:[9,2,1],state:2},{pos:[9,2,2],state:5},{pos:[9,2,3],state:2},{pos:[9,2,4],state:2},{pos:[9,2,5],state:2},{pos:[9,2,6],state:2},{pos:[9,2,7],state:5},{pos:[9,2,8],state:2},{pos:[9,2,9],state:2},{pos:[0,3,0],state:2},{pos:[0,3,1],state:2},{pos:[0,3,2],state:2},{pos:[0,3,3],state:2},{pos:[0,3,4],state:2},{pos:[0,3,5],state:2},{pos:[0,3,6],state:2},{pos:[0,3,7],state:2},{pos:[0,3,8],state:2},{pos:[0,3,9],state:2},{pos:[1,3,0],state:2},{pos:[1,3,9],state:2},{pos:[2,3,0],state:2},{pos:[2,3,9],state:2},{pos:[3,3,0],state:2},{pos:[3,3,9],state:2},{pos:[4,3,0],state:2},{pos:[4,3,9],state:2},{pos:[5,3,0],state:2},{pos:[5,3,1],state:10},{pos:[5,3,9],state:2},{pos:[6,3,0],state:2},{pos:[6,3,9],state:2},{pos:[7,3,0],state:2},{pos:[7,3,9],state:2},{pos:[8,3,0],state:2},{pos:[8,3,9],state:2},{pos:[9,3,0],state:2},{pos:[9,3,1],state:2},{pos:[9,3,2],state:2},{pos:[9,3,3],state:2},{pos:[9,3,4],state:2},{pos:[9,3,5],state:2},{pos:[9,3,6],state:2},{pos:[9,3,7],state:2},{pos:[9,3,8],state:2},{pos:[9,3,9],state:2},{pos:[0,4,0],state:2},{pos:[0,4,1],state:2},{pos:[0,4,2],state:2},{pos:[0,4,3],state:2},{pos:[0,4,4],state:2},{pos:[0,4,5],state:2},{pos:[0,4,6],state:2},{pos:[0,4,7],state:2},{pos:[0,4,8],state:2},{pos:[0,4,9],state:2},{pos:[1,4,0],state:2},{pos:[1,4,1],state:2},{pos:[1,4,2],state:2},{pos:[1,4,3],state:2},{pos:[1,4,4],state:2},{pos:[1,4,5],state:2},{pos:[1,4,6],state:2},{pos:[1,4,7],state:2},{pos:[1,4,8],state:2},{pos:[1,4,9],state:2},{pos:[2,4,0],state:2},{pos:[2,4,1],state:2},{pos:[2,4,2],state:2},{pos:[2,4,3],state:2},{pos:[2,4,4],state:2},{pos:[2,4,5],state:2},{pos:[2,4,6],state:2},{pos:[2,4,7],state:2},{pos:[2,4,8],state:2},{pos:[2,4,9],state:2},{pos:[3,4,0],state:2},{pos:[3,4,1],state:2},{pos:[3,4,2],state:2},{pos:[3,4,3],state:2},{pos:[3,4,4],state:2},{pos:[3,4,5],state:2},{pos:[3,4,6],state:2},{pos:[3,4,7],state:2},{pos:[3,4,8],state:2},{pos:[3,4,9],state:2},{pos:[4,4,0],state:2},{pos:[4,4,1],state:2},{pos:[4,4,2],state:2},{pos:[4,4,3],state:2},{pos:[4,4,4],state:2},{pos:[4,4,5],state:2},{pos:[4,4,6],state:2},{pos:[4,4,7],state:2},{pos:[4,4,8],state:2},{pos:[4,4,9],state:2},{pos:[5,4,0],state:2},{pos:[5,4,1],state:0},{pos:[5,4,2],state:2},{pos:[5,4,3],state:2},{pos:[5,4,4],state:2},{pos:[5,4,5],state:2},{pos:[5,4,6],state:2},{pos:[5,4,7],state:2},{pos:[5,4,8],state:2},{pos:[5,4,9],state:2},{pos:[6,4,0],state:2},{pos:[6,4,1],state:2},{pos:[6,4,2],state:2},{pos:[6,4,3],state:2},{pos:[6,4,4],state:2},{pos:[6,4,5],state:2},{pos:[6,4,6],state:2},{pos:[6,4,7],state:2},{pos:[6,4,8],state:2},{pos:[6,4,9],state:2},{pos:[7,4,0],state:2},{pos:[7,4,1],state:2},{pos:[7,4,2],state:2},{pos:[7,4,3],state:2},{pos:[7,4,4],state:2},{pos:[7,4,5],state:2},{pos:[7,4,6],state:2},{pos:[7,4,7],state:2},{pos:[7,4,8],state:2},{pos:[7,4,9],state:2},{pos:[8,4,0],state:2},{pos:[8,4,1],state:2},{pos:[8,4,2],state:2},{pos:[8,4,3],state:2},{pos:[8,4,4],state:2},{pos:[8,4,5],state:2},{pos:[8,4,6],state:2},{pos:[8,4,7],state:2},{pos:[8,4,8],state:2},{pos:[8,4,9],state:2},{pos:[9,4,0],state:2},{pos:[9,4,1],state:2},{pos:[9,4,2],state:2},{pos:[9,4,3],state:2},{pos:[9,4,4],state:2},{pos:[9,4,5],state:2},{pos:[9,4,6],state:2},{pos:[9,4,7],state:2},{pos:[9,4,8],state:2},{pos:[9,4,9],state:2},{pos:[0,5,0],state:2},{pos:[0,5,1],state:2},{pos:[0,5,2],state:2},{pos:[0,5,3],state:2},{pos:[0,5,4],state:2},{pos:[0,5,5],state:2},{pos:[0,5,6],state:2},{pos:[0,5,7],state:2},{pos:[0,5,8],state:2},{pos:[0,5,9],state:2},{pos:[1,5,0],state:2},{pos:[1,5,9],state:2},{pos:[2,5,0],state:2},{pos:[2,5,9],state:2},{pos:[3,5,0],state:2},{pos:[3,5,9],state:2},{pos:[4,5,0],state:2},{pos:[4,5,9],state:2},{pos:[5,5,0],state:2},{pos:[5,5,1],state:10},{pos:[5,5,9],state:2},{pos:[6,5,0],state:2},{pos:[6,5,9],state:2},{pos:[7,5,0],state:2},{pos:[7,5,9],state:2},{pos:[8,5,0],state:2},{pos:[8,5,9],state:2},{pos:[9,5,0],state:2},{pos:[9,5,1],state:2},{pos:[9,5,2],state:2},{pos:[9,5,3],state:2},{pos:[9,5,4],state:2},{pos:[9,5,5],state:2},{pos:[9,5,6],state:2},{pos:[9,5,7],state:2},{pos:[9,5,8],state:2},{pos:[9,5,9],state:2},{pos:[0,6,0],state:2},{pos:[0,6,1],state:2},{pos:[0,6,2],state:5},{pos:[0,6,3],state:2},{pos:[0,6,4],state:2},{pos:[0,6,5],state:2},{pos:[0,6,6],state:2},{pos:[0,6,7],state:5},{pos:[0,6,8],state:2},{pos:[0,6,9],state:2},{pos:[1,6,0],state:5},{pos:[1,6,9],state:5},{pos:[2,6,0],state:2},{pos:[2,6,9],state:2},{pos:[3,6,0],state:2},{pos:[3,6,9],state:2},{pos:[4,6,0],state:2},{pos:[4,6,9],state:2},{pos:[5,6,0],state:2},{pos:[5,6,1],state:10},{pos:[5,6,9],state:2},{pos:[6,6,0],state:2},{pos:[6,6,9],state:2},{pos:[7,6,0],state:2},{pos:[7,6,9],state:2},{pos:[8,6,0],state:5},{pos:[8,6,9],state:5},{pos:[9,6,0],state:2},{pos:[9,6,1],state:2},{pos:[9,6,2],state:5},{pos:[9,6,3],state:2},{pos:[9,6,4],state:2},{pos:[9,6,5],state:2},{pos:[9,6,6],state:2},{pos:[9,6,7],state:5},{pos:[9,6,8],state:2},{pos:[9,6,9],state:2},{pos:[0,7,0],state:2},{pos:[0,7,1],state:2},{pos:[0,7,2],state:2},{pos:[0,7,3],state:2},{pos:[0,7,4],state:2},{pos:[0,7,5],state:2},{pos:[0,7,6],state:2},{pos:[0,7,7],state:2},{pos:[0,7,8],state:2},{pos:[0,7,9],state:2},{pos:[1,7,0],state:2},{pos:[1,7,9],state:2},{pos:[2,7,0],state:2},{pos:[2,7,9],state:2},{pos:[3,7,0],state:2},{pos:[3,7,9],state:2},{pos:[4,7,0],state:2},{pos:[4,7,9],state:2},{pos:[5,7,0],state:2},{pos:[5,7,1],state:10},{pos:[5,7,9],state:2},{pos:[6,7,0],state:2},{pos:[6,7,9],state:2},{pos:[7,7,0],state:2},{pos:[7,7,9],state:2},{pos:[8,7,0],state:2},{pos:[8,7,9],state:2},{pos:[9,7,0],state:2},{pos:[9,7,1],state:2},{pos:[9,7,2],state:2},{pos:[9,7,3],state:2},{pos:[9,7,4],state:2},{pos:[9,7,5],state:2},{pos:[9,7,6],state:2},{pos:[9,7,7],state:2},{pos:[9,7,8],state:2},{pos:[9,7,9],state:2},{pos:[0,8,0],state:2},{pos:[0,8,1],state:2},{pos:[0,8,2],state:2},{pos:[0,8,3],state:2},{pos:[0,8,4],state:2},{pos:[0,8,5],state:2},{pos:[0,8,6],state:2},{pos:[0,8,7],state:2},{pos:[0,8,8],state:2},{pos:[0,8,9],state:2},{pos:[1,8,0],state:2},{pos:[1,8,1],state:2},{pos:[1,8,2],state:2},{pos:[1,8,3],state:2},{pos:[1,8,4],state:2},{pos:[1,8,5],state:2},{pos:[1,8,6],state:2},{pos:[1,8,7],state:2},{pos:[1,8,8],state:2},{pos:[1,8,9],state:2},{pos:[2,8,0],state:2},{pos:[2,8,1],state:2},{pos:[2,8,2],state:2},{pos:[2,8,3],state:2},{pos:[2,8,4],state:2},{pos:[2,8,5],state:2},{pos:[2,8,6],state:2},{pos:[2,8,7],state:2},{pos:[2,8,8],state:2},{pos:[2,8,9],state:2},{pos:[3,8,0],state:2},{pos:[3,8,1],state:2},{pos:[3,8,2],state:2},{pos:[3,8,3],state:2},{pos:[3,8,4],state:2},{pos:[3,8,5],state:2},{pos:[3,8,6],state:2},{pos:[3,8,7],state:2},{pos:[3,8,8],state:2},{pos:[3,8,9],state:2},{pos:[4,8,0],state:2},{pos:[4,8,1],state:2},{pos:[4,8,2],state:2},{pos:[4,8,3],state:2},{pos:[4,8,4],state:2},{pos:[4,8,5],state:2},{pos:[4,8,6],state:2},{pos:[4,8,7],state:2},{pos:[4,8,8],state:2},{pos:[4,8,9],state:2},{pos:[5,8,0],state:2},{pos:[5,8,1],state:2},{pos:[5,8,2],state:2},{pos:[5,8,3],state:2},{pos:[5,8,4],state:2},{pos:[5,8,5],state:2},{pos:[5,8,6],state:2},{pos:[5,8,7],state:2},{pos:[5,8,8],state:2},{pos:[5,8,9],state:2},{pos:[6,8,0],state:2},{pos:[6,8,1],state:2},{pos:[6,8,2],state:2},{pos:[6,8,3],state:2},{pos:[6,8,4],state:2},{pos:[6,8,5],state:2},{pos:[6,8,6],state:2},{pos:[6,8,7],state:2},{pos:[6,8,8],state:2},{pos:[6,8,9],state:2},{pos:[7,8,0],state:2},{pos:[7,8,1],state:2},{pos:[7,8,2],state:2},{pos:[7,8,3],state:2},{pos:[7,8,4],state:2},{pos:[7,8,5],state:2},{pos:[7,8,6],state:2},{pos:[7,8,7],state:2},{pos:[7,8,8],state:2},{pos:[7,8,9],state:2},{pos:[8,8,0],state:2},{pos:[8,8,1],state:2},{pos:[8,8,2],state:2},{pos:[8,8,3],state:2},{pos:[8,8,4],state:2},{pos:[8,8,5],state:2},{pos:[8,8,6],state:2},{pos:[8,8,7],state:2},{pos:[8,8,8],state:2},{pos:[8,8,9],state:2},{pos:[9,8,0],state:2},{pos:[9,8,1],state:2},{pos:[9,8,2],state:2},{pos:[9,8,3],state:2},{pos:[9,8,4],state:2},{pos:[9,8,5],state:2},{pos:[9,8,6],state:2},{pos:[9,8,7],state:2},{pos:[9,8,8],state:2},{pos:[9,8,9],state:2},{pos:[0,9,0],state:6},{pos:[0,9,1],state:6},{pos:[0,9,2],state:6},{pos:[0,9,3],state:6},{pos:[0,9,4],state:6},{pos:[0,9,5],state:6},{pos:[0,9,6],state:6},{pos:[0,9,7],state:6},{pos:[0,9,8],state:6},{pos:[0,9,9],state:6},{pos:[1,9,0],state:6},{pos:[1,9,1],state:6},{pos:[1,9,2],state:6},{pos:[1,9,3],state:6},{pos:[1,9,4],state:6},{pos:[1,9,5],state:6},{pos:[1,9,6],state:6},{pos:[1,9,7],state:6},{pos:[1,9,8],state:6},{pos:[1,9,9],state:6},{pos:[2,9,0],state:6},{pos:[2,9,1],state:6},{pos:[2,9,2],state:6},{pos:[2,9,3],state:6},{pos:[2,9,4],state:6},{pos:[2,9,5],state:6},{pos:[2,9,6],state:6},{pos:[2,9,7],state:6},{pos:[2,9,8],state:6},{pos:[2,9,9],state:6},{pos:[3,9,0],state:6},{pos:[3,9,1],state:6},{pos:[3,9,2],state:6},{pos:[3,9,3],state:6},{pos:[3,9,4],state:6},{pos:[3,9,5],state:6},{pos:[3,9,6],state:6},{pos:[3,9,7],state:6},{pos:[3,9,8],state:6},{pos:[3,9,9],state:6},{pos:[6,9,0],state:7},{pos:[6,9,1],state:7},{pos:[6,9,2],state:7},{pos:[6,9,3],state:7},{pos:[6,9,4],state:7},{pos:[6,9,5],state:7},{pos:[6,9,6],state:7},{pos:[6,9,7],state:7},{pos:[6,9,8],state:7},{pos:[6,9,9],state:7},{pos:[7,9,0],state:7},{pos:[7,9,1],state:7},{pos:[7,9,2],state:7},{pos:[7,9,3],state:7},{pos:[7,9,4],state:7},{pos:[7,9,5],state:7},{pos:[7,9,6],state:7},{pos:[7,9,7],state:7},{pos:[7,9,8],state:7},{pos:[7,9,9],state:7},{pos:[8,9,0],state:7},{pos:[8,9,1],state:7},{pos:[8,9,2],state:7},{pos:[8,9,3],state:7},{pos:[8,9,4],state:7},{pos:[8,9,5],state:7},{pos:[8,9,6],state:7},{pos:[8,9,7],state:7},{pos:[8,9,8],state:7},{pos:[8,9,9],state:7},{pos:[9,9,0],state:7},{pos:[9,9,1],state:7},{pos:[9,9,2],state:7},{pos:[9,9,3],state:7},{pos:[9,9,4],state:7},{pos:[9,9,5],state:7},{pos:[9,9,6],state:7},{pos:[9,9,7],state:7},{pos:[9,9,8],state:7},{pos:[9,9,9],state:7},{pos:[4,10,0],state:8},{pos:[4,10,1],state:8},{pos:[4,10,2],state:8},{pos:[4,10,3],state:8},{pos:[4,10,4],state:8},{pos:[4,10,5],state:8},{pos:[4,10,6],state:8},{pos:[4,10,7],state:8},{pos:[4,10,8],state:8},{pos:[4,10,9],state:8},{pos:[5,10,0],state:9},{pos:[5,10,1],state:9},{pos:[5,10,2],state:9},{pos:[5,10,3],state:9},{pos:[5,10,4],state:9},{pos:[5,10,5],state:9},{pos:[5,10,6],state:9},{pos:[5,10,7],state:9},{pos:[5,10,8],state:9},{pos:[5,10,9],state:9}],entities:[]}