{
  size:[9,4,9],
  palette:[
    {Name:"minecraft:air"},
    {Name:"minecraft:campfire",Properties:{facing:"north",lit:"true",signal_fire:"false",waterlogged:"false"}},
    {Name:"minecraft:cobblestone"},
    {Name:"minecraft:cracked_deepslate_tiles"},
    {Name:"minecraft:andesite"},
    {Name:"minecraft:brown_wool"},
    {Name:"minecraft:gray_wool"},
    {Name:"minecraft:spruce_fence"},
    {Name:"minecraft:brown_carpet"},
    {Name:"minecraft:barrel",Properties:{facing:"north"}},
    {Name:"minecraft:dark_oak_trapdoor",Properties:{facing:"south",half:"bottom",open:"false",powered:"false",waterlogged:"false"}},
    {Name:"minecraft:cobweb"},
    {Name:"minecraft:spruce_fence_gate",Properties:{facing:"south",in_wall:"false",open:"true",powered:"false"}},
    {Name:"minecraft:spruce_log",Properties:{axis:"y"}}
  ],
  blocks:[
    {state:1,pos:[4,0,4]},

    {state:2,pos:[4,0,3]},
    {state:2,pos:[4,0,5]},
    {state:2,pos:[3,0,4]},
    {state:2,pos:[5,0,4]},

    {state:3,pos:[3,0,3]},
    {state:3,pos:[5,0,3]},
    {state:3,pos:[3,0,5]},
    {state:3,pos:[5,0,5]},

    {state:4,pos:[4,0,2]},
    {state:4,pos:[4,0,6]},


    {state:5,pos:[1,1,3]},
    {state:5,pos:[2,1,3]},
    {state:5,pos:[3,1,3]},

    {state:5,pos:[1,1,4]},

    {state:5,pos:[1,1,5]},
    {state:5,pos:[2,1,5]},
    {state:5,pos:[3,1,5]},

    {state:5,pos:[1,1,4]},
    {state:5,pos:[1,1,3]},
    {state:5,pos:[1,1,5]},
    {state:5,pos:[3,1,3]},
    {state:5,pos:[3,1,5]},

    {state:5,pos:[2,2,4]},
    {state:5,pos:[2,2,3]},
    {state:5,pos:[2,2,5]},


    {state:5,pos:[1,2,4]},
    {state:7,pos:[3,2,4]},

    {state:8,pos:[2,1,4]},


    {state:6,pos:[5,1,3]},
    {state:6,pos:[6,1,3]},
    {state:6,pos:[7,1,3]},

    {state:6,pos:[6,1,4]},
    {state:6,pos:[7,1,4]},

    {state:6,pos:[5,1,5]},
    {state:6,pos:[6,1,5]},
    {state:6,pos:[7,1,5]},

    {state:6,pos:[6,2,4]},   
    {state:6,pos:[6,2,3]},
    {state:6,pos:[6,2,5]},
    {state:6,pos:[5,2,4]},
    {state:7,pos:[7,2,4]},

    {state:9,pos:[6,0,4]},
    {state:10,pos:[6,1,4]},

    {state:11,pos:[7,1,3]},


    {state:7,pos:[2,1,1]},
    {state:7,pos:[3,1,1]},
    {state:7,pos:[4,1,1]},
    {state:7,pos:[5,1,1]},
    {state:7,pos:[6,1,1]},

    {state:13,pos:[4,0,1]},


    {state:12,pos:[4,1,2]}
  ],
  entities:[],
  DataVersion:3465
}