{DataVersion:3465,size:[5,4,5],palette:[{Name:"minecraft:air"},{Name:"minecraft:cobblestone"},{Name:"minecraft:oak_planks"},{Name:"minecraft:oak_log",Properties:{axis:"y"}},{Name:"minecraft:glass_pane"},{Name:"minecraft:oak_door",Properties:{facing:"south",half:"lower",hinge:"right"}},{Name:"minecraft:oak_door",Properties:{facing:"south",half:"upper",hinge:"right"}},{Name:"minecraft:oak_stairs",Properties:{facing:"east",half:"bottom",shape:"straight"}},{Name:"minecraft:oak_stairs",Properties:{facing:"west",half:"bottom",shape:"straight"}},{Name:"minecraft:oak_slab",Properties:{type:"top"}}],blocks:[{pos:[0,0,0],state:2},{pos:[1,0,0],state:2},{pos:[2,0,0],state:2},{pos:[3,0,0],state:2},{pos:[4,0,0],state:2},{pos:[0,0,1],state:2},{pos:[1,0,1],state:2},{pos:[2,0,1],state:2},{pos:[3,0,1],state:2},{pos:[4,0,1],state:2},{pos:[0,0,2],state:2},{pos:[1,0,2],state:2},{pos:[2,0,2],state:2},{pos:[3,0,2],state:2},{pos:[4,0,2],state:2},{pos:[0,0,3],state:2},{pos:[1,0,3],state:2},{pos:[2,0,3],state:2},{pos:[3,0,3],state:2},{pos:[4,0,3],state:2},{pos:[0,0,4],state:2},{pos:[1,0,4],state:2},{pos:[2,0,4],state:2},{pos:[3,0,4],state:2},{pos:[4,0,4],state:2},{pos:[1,1,1],state:0},{pos:[1,1,2],state:0},{pos:[1,1,3],state:0},{pos:[2,1,1],state:0},{pos:[2,1,2],state:0},{pos:[2,1,3],state:0},{pos:[3,1,1],state:0},{pos:[3,1,2],state:0},{pos:[3,1,3],state:0},{pos:[1,2,1],state:0},{pos:[1,2,2],state:0},{pos:[1,2,3],state:0},{pos:[2,2,1],state:0},{pos:[2,2,2],state:0},{pos:[2,2,3],state:0},{pos:[3,2,1],state:0},{pos:[3,2,2],state:0},{pos:[3,2,3],state:0},{pos:[0,1,0],state:3},{pos:[4,1,0],state:3},{pos:[0,1,4],state:3},{pos:[4,1,4],state:3},{pos:[0,2,0],state:3},{pos:[4,2,0],state:3},{pos:[0,2,4],state:3},{pos:[4,2,4],state:3},{pos:[1,1,0],state:1},{pos:[3,1,0],state:1},{pos:[1,1,4],state:1},{pos:[2,1,4],state:1},{pos:[3,1,4],state:1},{pos:[0,1,1],state:1},{pos:[0,1,2],state:1},{pos:[0,1,3],state:1},{pos:[4,1,1],state:1},{pos:[4,1,2],state:1},{pos:[4,1,3],state:1},{pos:[2,1,0],state:5},{pos:[1,2,0],state:4},{pos:[3,2,0],state:4},{pos:[1,2,4],state:2},{pos:[2,2,4],state:2},{pos:[3,2,4],state:2},{pos:[0,2,1],state:2},{pos:[0,2,2],state:4},{pos:[0,2,3],state:2},{pos:[4,2,1],state:2},{pos:[4,2,2],state:4},{pos:[4,2,3],state:2},{pos:[2,2,0],state:6},{pos:[0,3,0],state:7},{pos:[0,3,1],state:7},{pos:[0,3,2],state:7},{pos:[0,3,3],state:7},{pos:[0,3,4],state:7},{pos:[1,3,0],state:7},{pos:[1,3,1],state:7},{pos:[1,3,2],state:7},{pos:[1,3,3],state:7},{pos:[1,3,4],state:7},{pos:[3,3,0],state:8},{pos:[3,3,1],state:8},{pos:[3,3,2],state:8},{pos:[3,3,3],state:8},{pos:[3,3,4],state:8},{pos:[4,3,0],state:8},{pos:[4,3,1],state:8},{pos:[4,3,2],state:8},{pos:[4,3,3],state:8},{pos:[4,3,4],state:8},{pos:[2,3,0],state:9},{pos:[2,3,1],state:9},{pos:[2,3,2],state:9},{pos:[2,3,3],state:9},{pos:[2,3,4],state:9}],entities:[]}